<?xml version="1.0" ?>
<!-- =================================================================================== -->
<!-- |    This document was autogenerated by xacro from subwoofer.urdf.xacro           | -->
<!-- |    EDITING THIS FILE BY HAND IS NOT RECOMMENDED                                 | -->
<!-- =================================================================================== -->
<robot name="Subwoofer">
  <!-- Colour codes -->
  <!-- Supernova: 1.0 0.793 0.0 -->
  <!-- Port Gore: 0.141 0.152 0.328 -->
  <!-- Colour codes -->
  <!-- Supernova: 1.0 0.793 0.0 -->
  <!-- Port Gore: 0.141 0.152 0.328 -->
  <!-- Colour codes -->
  <!-- Supernova: 1.0 0.793 0.0 -->
  <!-- Port Gore: 0.141 0.152 0.328 -->
  <!-- Colour codes -->
  <!-- Supernova: 1.0 0.793 0.0 -->
  <!-- Port Gore: 0.141 0.152 0.328 -->
  <material name="BLACK">
    <color rgba="0.0 0.0 0.0 1.0"/>
  </material>
  <material name="RED">
    <color rgba="1.0 0.0 0.0 1.0"/>
  </material>
  <material name="WHITE">
    <color rgba="1.0 1.0 1.0 1.0"/>
  </material>
  <link name="world"/>
  <joint name="world_joint" type="fixed">
    <parent link="world"/>
    <child link="base_link"/>
  </joint>
  <link name="base_link"/>
  <joint name="baseplate_to_base_link" type="fixed">
    <parent link="base_link"/>
    <child link="baseplate"/>
    <origin rpy="0 0 0" xyz="0 0 0"/>
  </joint>
  <link name="baseplate">
    <inertial>
      <mass value="0.050"/>
      <inertia ixx="1e-3" ixy="0.0" ixz="0.0" iyy="1e-3" iyz="0.0" izz="1e-3"/>
    </inertial>
    <visual>
      <origin rpy="0 0 0" xyz="-0.15059999999999998 -0.1519 -0.4"/>
      <geometry>
        <mesh filename="package://subwoofer_model/meshes/V1.02_Chassis_BasePlate_RPi4.stl" scale="0.001 0.001 0.001"/>
      </geometry>
    </visual>
    <collision>
      <origin rpy="0 0 0" xyz="-0.15059999999999998 -0.1519 -0.4"/>
      <geometry>
        <mesh filename="package://subwoofer_model/meshes/V1.02_Chassis_BasePlate_RPi4.stl" scale="0.001 0.001 0.001"/>
      </geometry>
    </collision>
  </link>
  <link name="front_inner_shoulder">
    <inertial>
      <mass value="0.050"/>
      <inertia ixx="1e-3" ixy="0.0" ixz="0.0" iyy="1e-3" iyz="0.0" izz="1e-3"/>
    </inertial>
    <visual>
      <origin rpy="1.57075 0 3.1415" xyz="-0.034 -0.002 0.033"/>
      <geometry>
        <mesh filename="package://subwoofer_model/meshes/V1.02_Front_Inner_Shoulder.dae" scale="0.001 0.001 0.001"/>
      </geometry>
    </visual>
    <collision>
      <origin rpy="1.57075 0 3.1415" xyz="-0.034 -0.002 0.033"/>
      <geometry>
        <mesh filename="package://subwoofer_model/meshes/V1.02_Front_Inner_Shoulder.dae" scale="0.001 0.001 0.001"/>
      </geometry>
    </collision>
  </link>
  <joint name="front_inner_shoulder_to_baseplate" type="fixed">
    <parent link="baseplate"/>
    <child link="front_inner_shoulder"/>
    <origin rpy="0 0 0" xyz="0.0 0.065 0.01"/>
  </joint>
  <link name="left_chassis">
    <inertial>
      <mass value="0.050"/>
      <inertia ixx="1e-3" ixy="0.0" ixz="0.0" iyy="1e-3" iyz="0.0" izz="1e-3"/>
    </inertial>
    <visual>
      <origin rpy="0 0 0" xyz="0.0 0.0 0.0"/>
      <geometry>
        <mesh filename="package://subwoofer_model/meshes/V1.02_Chassis_Left_Side.dae" scale="0.001 0.001 0.001"/>
      </geometry>
    </visual>
    <collision>
      <origin rpy="0 0 0" xyz="0.0 0.0 0.0"/>
      <geometry>
        <mesh filename="package://subwoofer_model/meshes/V1.02_Chassis_Left_Side.dae" scale="0.001 0.001 0.001"/>
      </geometry>
    </collision>
  </link>
  <joint name="left_chassis_to_front_inner_shoulder" type="fixed">
    <parent link="front_inner_shoulder"/>
    <child link="left_chassis"/>
    <origin rpy="0 -1.57075 3.1415" xyz="-0.054 -0.0655 0.0005"/>
  </joint>
  <link name="right_chassis">
    <inertial>
      <mass value="0.050"/>
      <inertia ixx="1e-3" ixy="0.0" ixz="0.0" iyy="1e-3" iyz="0.0" izz="1e-3"/>
    </inertial>
    <visual>
      <origin rpy="0 0 0" xyz="0.0 0.0 0.0"/>
      <geometry>
        <mesh filename="package://subwoofer_model/meshes/V1.02_Chassis_Right_Side.dae" scale="0.001 0.001 0.001"/>
      </geometry>
    </visual>
    <collision>
      <origin rpy="0 0 0" xyz="0.0 0.0 0.0"/>
      <geometry>
        <mesh filename="package://subwoofer_model/meshes/V1.02_Chassis_Right_Side.dae" scale="0.001 0.001 0.001"/>
      </geometry>
    </collision>
  </link>
  <joint name="right_chassis_to_front_inner_shoulder" type="fixed">
    <parent link="front_inner_shoulder"/>
    <child link="right_chassis"/>
    <origin rpy="0 -1.57075 0" xyz="0.054 -0.0655 0.0005"/>
  </joint>
  <link name="back_inner_shoulder">
    <inertial>
      <mass value="0.050"/>
      <inertia ixx="1e-3" ixy="0.0" ixz="0.0" iyy="1e-3" iyz="0.0" izz="1e-3"/>
    </inertial>
    <visual>
      <origin rpy="3.1415 0 0" xyz="-0.116 0.002 0.467"/>
      <geometry>
        <mesh filename="package://subwoofer_model/meshes/V1.02_Rear_Inner_Shoulder.dae" scale="0.001 0.001 0.001"/>
      </geometry>
    </visual>
    <collision>
      <origin rpy="3.1415 0 0" xyz="-0.116 0.002 0.467"/>
      <geometry>
        <mesh filename="package://subwoofer_model/meshes/V1.02_Rear_Inner_Shoulder.dae" scale="0.001 0.001 0.001"/>
      </geometry>
    </collision>
  </link>
  <joint name="back_inner_shoulder_to_baseplate" type="fixed">
    <parent link="baseplate"/>
    <child link="back_inner_shoulder"/>
    <origin rpy="0 0 0" xyz="0.0 -0.066 0.01"/>
  </joint>
  <link name="bottom_chassis">
    <inertial>
      <mass value="0.050"/>
      <inertia ixx="1e-3" ixy="0.0" ixz="0.0" iyy="1e-3" iyz="0.0" izz="1e-3"/>
    </inertial>
    <visual>
      <origin rpy="1.57075 0 -1.57075" xyz="1.004 1.0150000000000001 1.292"/>
      <geometry>
        <mesh filename="package://subwoofer_model/meshes/V1.02_Cover_Bottom.dae" scale="0.001 0.001 0.001"/>
      </geometry>
    </visual>
    <collision>
      <origin rpy="1.57075 0 -1.57075" xyz="1.004 1.0150000000000001 1.292"/>
      <geometry>
        <mesh filename="package://subwoofer_model/meshes/V1.02_Cover_Bottom.dae" scale="0.001 0.001 0.001"/>
      </geometry>
    </collision>
  </link>
  <joint name="bottom_chassis_to_baseplate" type="fixed">
    <parent link="baseplate"/>
    <child link="bottom_chassis"/>
    <origin rpy="0 0 0" xyz="0.0 0.0 -0.028"/>
  </joint>
  <link name="top_chassis">
    <inertial>
      <mass value="0.050"/>
      <inertia ixx="1e-3" ixy="0.0" ixz="0.0" iyy="1e-3" iyz="0.0" izz="1e-3"/>
    </inertial>
    <visual>
      <origin rpy="-1.57075 0 1.57075" xyz="1.004 -1.016 -1.292"/>
      <geometry>
        <mesh filename="package://subwoofer_model/meshes/V1.02_Cover_Top.dae" scale="0.001 0.001 0.001"/>
      </geometry>
    </visual>
    <collision>
      <origin rpy="-1.57075 0 1.57075" xyz="1.004 -1.016 -1.292"/>
      <geometry>
        <mesh filename="package://subwoofer_model/meshes/V1.02_Cover_Top.dae" scale="0.001 0.001 0.001"/>
      </geometry>
    </collision>
  </link>
  <joint name="top_chassis_to_bottom_chassis" type="fixed">
    <parent link="bottom_chassis"/>
    <child link="top_chassis"/>
    <origin rpy="0 0 0" xyz="0.0 0.0 0.07200000000000001"/>
  </joint>
  <link name="front_outer_shoulder">
    <inertial>
      <mass value="0.050"/>
      <inertia ixx="1e-3" ixy="0.0" ixz="0.0" iyy="1e-3" iyz="0.0" izz="1e-3"/>
    </inertial>
    <visual>
      <origin rpy="0 3.1415 3.1415" xyz="-0.1155 0.002 0.467"/>
      <geometry>
        <mesh filename="package://subwoofer_model/meshes/V1.02_Front_Outer_Shoulder.dae" scale="0.001 0.001 0.001"/>
      </geometry>
    </visual>
    <collision>
      <origin rpy="0 3.1415 3.1415" xyz="-0.1155 0.002 0.467"/>
      <geometry>
        <mesh filename="package://subwoofer_model/meshes/V1.02_Front_Outer_Shoulder.dae" scale="0.001 0.001 0.001"/>
      </geometry>
    </collision>
  </link>
  <joint name="front_outer_shoulder_to_front_inner_shoulder" type="fixed">
    <parent link="front_inner_shoulder"/>
    <child link="front_outer_shoulder"/>
    <origin rpy="0 0 0" xyz="0.0 0.054 0.0"/>
  </joint>
  <link name="nose_chassis">
    <inertial>
      <mass value="0.050"/>
      <inertia ixx="1e-3" ixy="0.0" ixz="0.0" iyy="1e-3" iyz="0.0" izz="1e-3"/>
    </inertial>
    <visual>
      <origin rpy="3.1415 0 1.57075" xyz="0.14200000000000002 0.355 0.51"/>
      <geometry>
        <mesh filename="package://subwoofer_model/meshes/V1.02_Cover_Nose.dae" scale="0.001 0.001 0.001"/>
      </geometry>
    </visual>
    <collision>
      <origin rpy="3.1415 0 1.57075" xyz="0.14200000000000002 0.355 0.51"/>
      <geometry>
        <mesh filename="package://subwoofer_model/meshes/V1.02_Cover_Nose.dae" scale="0.001 0.001 0.001"/>
      </geometry>
    </collision>
  </link>
  <joint name="nose_chassis_to_front_inner_shoulder" type="fixed">
    <parent link="front_inner_shoulder"/>
    <child link="nose_chassis"/>
    <origin rpy="0 0 0" xyz="0.0 0.074 -0.0075"/>
  </joint>
  <link name="back_outer_shoulder">
    <inertial>
      <mass value="0.050"/>
      <inertia ixx="1e-3" ixy="0.0" ixz="0.0" iyy="1e-3" iyz="0.0" izz="1e-3"/>
    </inertial>
    <visual>
      <origin rpy="0 0 3.1415" xyz="0.117 0.055 -0.47000000000000003"/>
      <geometry>
        <mesh filename="package://subwoofer_model/meshes/V1.02_Rear_Outer_Shoulder.dae" scale="0.001 0.001 0.001"/>
      </geometry>
    </visual>
    <collision>
      <origin rpy="0 0 3.1415" xyz="0.117 0.055 -0.47000000000000003"/>
      <geometry>
        <mesh filename="package://subwoofer_model/meshes/V1.02_Rear_Outer_Shoulder.dae" scale="0.001 0.001 0.001"/>
      </geometry>
    </collision>
  </link>
  <joint name="back_outer_shoulder_to_back_inner_shoulder" type="fixed">
    <parent link="back_inner_shoulder"/>
    <child link="back_outer_shoulder"/>
    <origin rpy="0 0 0" xyz="0.0 -0.053 0.0"/>
  </joint>
  <link name="rear_chassis">
    <inertial>
      <mass value="0.050"/>
      <inertia ixx="1e-3" ixy="0.0" ixz="0.0" iyy="1e-3" iyz="0.0" izz="1e-3"/>
    </inertial>
    <visual>
      <origin rpy="0 1.57075 1.57075" xyz="0.2487 0.252 0.38"/>
      <geometry>
        <mesh filename="package://subwoofer_model/meshes/V1.02_Cover_Rear_Plain.dae" scale="0.001 0.001 0.001"/>
      </geometry>
    </visual>
    <collision>
      <origin rpy="0 1.57075 1.57075" xyz="0.2487 0.252 0.38"/>
      <geometry>
        <mesh filename="package://subwoofer_model/meshes/V1.02_Cover_Rear_Plain.dae" scale="0.001 0.001 0.001"/>
      </geometry>
    </collision>
  </link>
  <joint name="rear_chassis_to_back_inner_shoulder" type="fixed">
    <parent link="back_inner_shoulder"/>
    <child link="rear_chassis"/>
    <origin rpy="0 0 0" xyz="0.0 -0.079 0.0"/>
  </joint>
  <link name="front_left_hip_servo">
    <inertial>
      <mass value="0.050"/>
      <inertia ixx="1e-3" ixy="0.0" ixz="0.0" iyy="1e-3" iyz="0.0" izz="1e-3"/>
    </inertial>
    <visual>
      <origin rpy="0 3.1415 1.57075" xyz="0.043000000000000003 0.0 -0.01"/>
      <geometry>
        <mesh filename="package://subwoofer_model/meshes/Servo.dae" scale="0.001 0.001 0.001"/>
      </geometry>
    </visual>
    <collision>
      <origin rpy="0 3.1415 1.57075" xyz="0.043000000000000003 0.0 -0.01"/>
      <geometry>
        <mesh filename="package://subwoofer_model/meshes/Servo.dae" scale="0.001 0.001 0.001"/>
      </geometry>
    </collision>
  </link>
  <joint name="front_left_hip_servo_to_front_outer_shoulder" type="revolute">
    <parent link="front_outer_shoulder"/>
    <child link="front_left_hip_servo"/>
    <axis xyz="1 0 0"/>
    <limit effort="1000.0" lower="-0.78" upper="0.78" velocity="0.5"/>
    <origin rpy="0 0 -1.57075" xyz="-0.037 0.0 0.007"/>
    <dynamics damping="0.05" friction="0.05"/>
  </joint>
  <link name="front_left_hip">
    <inertial>
      <mass value="0.050"/>
      <inertia ixx="1e-3" ixy="0.0" ixz="0.0" iyy="1e-3" iyz="0.0" izz="1e-3"/>
    </inertial>
    <visual>
      <origin rpy="0 0 0" xyz="0.003 -0.023 -0.026000000000000002"/>
      <geometry>
        <mesh filename="package://subwoofer_model/meshes/V1.02_Left_Hind_Limb.dae" scale="0.001 0.001 0.001"/>
      </geometry>
    </visual>
    <collision>
      <origin rpy="0 0 0" xyz="0.003 -0.023 -0.026000000000000002"/>
      <geometry>
        <mesh filename="package://subwoofer_model/meshes/V1.02_Left_Hind_Limb.dae" scale="0.001 0.001 0.001"/>
      </geometry>
    </collision>
  </link>
  <joint name="front_left_hip_to_front_left_hip_servo" type="fixed">
    <parent link="front_left_hip_servo"/>
    <child link="front_left_hip"/>
    <origin rpy="0 0 -1.57075" xyz="0.0272 -0.025 -0.01"/>
  </joint>
  <link name="front_left_midlimb_servo">
    <inertial>
      <mass value="0.050"/>
      <inertia ixx="1e-3" ixy="0.0" ixz="0.0" iyy="1e-3" iyz="0.0" izz="1e-3"/>
    </inertial>
    <visual>
      <origin rpy="0 3.1415 1.57075" xyz="0.043000000000000003 0.0 -0.01"/>
      <geometry>
        <mesh filename="package://subwoofer_model/meshes/Servo.dae" scale="0.001 0.001 0.001"/>
      </geometry>
    </visual>
    <collision>
      <origin rpy="0 3.1415 1.57075" xyz="0.043000000000000003 0.0 -0.01"/>
      <geometry>
        <mesh filename="package://subwoofer_model/meshes/Servo.dae" scale="0.001 0.001 0.001"/>
      </geometry>
    </collision>
  </link>
  <joint name="front_left_midlimb_servo_to_front_left_hip" type="revolute">
    <parent link="front_left_hip"/>
    <child link="front_left_midlimb_servo"/>
    <axis xyz="1 0 0"/>
    <limit effort="1000.0" lower="-1.57" upper="1.57" velocity="0.5"/>
    <origin rpy="0 0 0" xyz="0 0 0"/>
    <dynamics damping="0.05" friction="0.05"/>
  </joint>
  <link name="front_left_midlimb">
    <inertial>
      <mass value="0.050"/>
      <inertia ixx="1e-3" ixy="0.0" ixz="0.0" iyy="1e-3" iyz="0.0" izz="1e-3"/>
    </inertial>
    <visual>
      <origin rpy="0 3.1415 0" xyz="-0.048 -0.02 0.8250000000000001"/>
      <geometry>
        <mesh filename="package://subwoofer_model/meshes/V1.02_Left_MidLimb.dae" scale="0.001 0.001 0.001"/>
      </geometry>
    </visual>
    <collision>
      <origin rpy="0 3.1415 0" xyz="-0.048 -0.02 0.8250000000000001"/>
      <geometry>
        <mesh filename="package://subwoofer_model/meshes/V1.02_Left_MidLimb.dae" scale="0.001 0.001 0.001"/>
      </geometry>
    </collision>
  </link>
  <joint name="front_left_midlimb_to_front_left_midlimb_servo" type="fixed">
    <parent link="front_left_midlimb_servo"/>
    <child link="front_left_midlimb"/>
    <origin rpy="0 0 -1.57075" xyz="0.009000000000000001 -0.013000000000000001 -0.107"/>
  </joint>
  <link name="front_left_midlimb_cover">
    <inertial>
      <mass value="0.050"/>
      <inertia ixx="1e-3" ixy="0.0" ixz="0.0" iyy="1e-3" iyz="0.0" izz="1e-3"/>
    </inertial>
    <visual>
      <origin rpy="0 3.1415 0" xyz="0.256 -0.11 0.926"/>
      <geometry>
        <mesh filename="package://subwoofer_model/meshes/V1.02_Left_MidLimb_Cover.dae" scale="0.001 0.001 0.001"/>
      </geometry>
    </visual>
    <collision>
      <origin rpy="0 3.1415 0" xyz="0.256 -0.11 0.926"/>
      <geometry>
        <mesh filename="package://subwoofer_model/meshes/V1.02_Left_MidLimb_Cover.dae" scale="0.001 0.001 0.001"/>
      </geometry>
    </collision>
  </link>
  <joint name="front_left_midlimb_cover_to_front_left_midlimb" type="fixed">
    <parent link="front_left_midlimb"/>
    <child link="front_left_midlimb_cover"/>
    <origin rpy="0 0 0" xyz="0 0.0497 0"/>
  </joint>
  <link name="front_left_wrist_servo">
    <inertial>
      <mass value="0.050"/>
      <inertia ixx="1e-3" ixy="0.0" ixz="0.0" iyy="1e-3" iyz="0.0" izz="1e-3"/>
    </inertial>
    <visual>
      <origin rpy="0 3.1415 1.57075" xyz="0.043000000000000003 0.0 -0.01"/>
      <geometry>
        <mesh filename="package://subwoofer_model/meshes/Servo.dae" scale="0.001 0.001 0.001"/>
      </geometry>
    </visual>
    <collision>
      <origin rpy="0 3.1415 1.57075" xyz="0.043000000000000003 0.0 -0.01"/>
      <geometry>
        <mesh filename="package://subwoofer_model/meshes/Servo.dae" scale="0.001 0.001 0.001"/>
      </geometry>
    </collision>
  </link>
  <joint name="front_left_wrist_servo_to_front_left_midlimb" type="revolute">
    <parent link="front_left_midlimb"/>
    <child link="front_left_wrist_servo"/>
    <axis xyz="1 0 0"/>
    <limit effort="1000.0" lower="-2.6" upper="1.1" velocity="0.5"/>
    <origin rpy="0 0 1.57075" xyz="0 0 0"/>
    <dynamics damping="0.05" friction="0.05"/>
  </joint>
  <link name="front_left_wrist">
    <inertial>
      <mass value="0.050"/>
      <inertia ixx="1e-3" ixy="0.0" ixz="0.0" iyy="1e-3" iyz="0.0" izz="1e-3"/>
    </inertial>
    <visual>
      <origin rpy="0 1.57075 -1.57075" xyz="0.507 0.23500000000000001 0.148"/>
      <geometry>
        <mesh filename="package://subwoofer_model/meshes/V1.02_Left_Wrist.dae" scale="0.001 0.001 0.001"/>
      </geometry>
    </visual>
    <collision>
      <origin rpy="0 1.57075 -1.57075" xyz="0.507 0.23500000000000001 0.148"/>
      <geometry>
        <mesh filename="package://subwoofer_model/meshes/V1.02_Left_Wrist.dae" scale="0.001 0.001 0.001"/>
      </geometry>
    </collision>
  </link>
  <joint name="front_left_wrist_to_front_left_wrist_servo" type="fixed">
    <parent link="front_left_wrist_servo"/>
    <child link="front_left_wrist"/>
    <origin rpy="0 0 3.1415" xyz="0.053 0 0"/>
  </joint>
  <link name="front_right_hip_servo">
    <inertial>
      <mass value="0.050"/>
      <inertia ixx="1e-3" ixy="0.0" ixz="0.0" iyy="1e-3" iyz="0.0" izz="1e-3"/>
    </inertial>
    <visual>
      <origin rpy="0 3.1415 1.57075" xyz="0.043000000000000003 0.0 -0.01"/>
      <geometry>
        <mesh filename="package://subwoofer_model/meshes/Servo.dae" scale="0.001 0.001 0.001"/>
      </geometry>
    </visual>
    <collision>
      <origin rpy="0 3.1415 1.57075" xyz="0.043000000000000003 0.0 -0.01"/>
      <geometry>
        <mesh filename="package://subwoofer_model/meshes/Servo.dae" scale="0.001 0.001 0.001"/>
      </geometry>
    </collision>
  </link>
  <joint name="front_right_hip_servo_to_front_outer_shoulder" type="revolute">
    <parent link="front_outer_shoulder"/>
    <child link="front_right_hip_servo"/>
    <axis xyz="1 0 0"/>
    <limit effort="1000.0" lower="-0.78" upper="0.78" velocity="0.5"/>
    <origin rpy="0 0 -1.57075" xyz="0.037 0.0 0.007"/>
    <dynamics damping="0.05" friction="0.05"/>
  </joint>
  <link name="front_right_hip">
    <inertial>
      <mass value="0.050"/>
      <inertia ixx="1e-3" ixy="0.0" ixz="0.0" iyy="1e-3" iyz="0.0" izz="1e-3"/>
    </inertial>
    <visual>
      <origin rpy="3.1415 0 0" xyz="-0.12 0.10300000000000001 0.0282"/>
      <geometry>
        <mesh filename="package://subwoofer_model/meshes/V1.02_Right_Hind_Limb.dae" scale="0.001 0.001 0.001"/>
      </geometry>
    </visual>
    <collision>
      <origin rpy="3.1415 0 0" xyz="-0.12 0.10300000000000001 0.0282"/>
      <geometry>
        <mesh filename="package://subwoofer_model/meshes/V1.02_Right_Hind_Limb.dae" scale="0.001 0.001 0.001"/>
      </geometry>
    </collision>
  </link>
  <joint name="front_right_hip_to_front_right_hip_servo" type="fixed">
    <parent link="front_right_hip_servo"/>
    <child link="front_right_hip"/>
    <origin rpy="0 0 1.57075" xyz="0.0272 0.025 -0.01"/>
  </joint>
  <link name="front_right_midlimb_servo">
    <inertial>
      <mass value="0.050"/>
      <inertia ixx="1e-3" ixy="0.0" ixz="0.0" iyy="1e-3" iyz="0.0" izz="1e-3"/>
    </inertial>
    <visual>
      <origin rpy="0 3.1415 1.57075" xyz="0.043000000000000003 0.0 -0.01"/>
      <geometry>
        <mesh filename="package://subwoofer_model/meshes/Servo.dae" scale="0.001 0.001 0.001"/>
      </geometry>
    </visual>
    <collision>
      <origin rpy="0 3.1415 1.57075" xyz="0.043000000000000003 0.0 -0.01"/>
      <geometry>
        <mesh filename="package://subwoofer_model/meshes/Servo.dae" scale="0.001 0.001 0.001"/>
      </geometry>
    </collision>
  </link>
  <joint name="front_right_midlimb_servo_to_front_right_hip" type="revolute">
    <parent link="front_right_hip"/>
    <child link="front_right_midlimb_servo"/>
    <axis xyz="1 0 0"/>
    <limit effort="1000.0" lower="-1.57" upper="1.57" velocity="0.5"/>
    <origin rpy="0 0 0" xyz="0 0 0"/>
    <dynamics damping="0.05" friction="0.05"/>
  </joint>
  <link name="front_right_midlimb">
    <inertial>
      <mass value="0.050"/>
      <inertia ixx="1e-3" ixy="0.0" ixz="0.0" iyy="1e-3" iyz="0.0" izz="1e-3"/>
    </inertial>
    <visual>
      <origin rpy="0 0 0" xyz="0.048 -0.02 0.8250000000000001"/>
      <geometry>
        <mesh filename="package://subwoofer_model/meshes/V1.02_Right_MidLimb.dae" scale="0.001 0.001 0.001"/>
      </geometry>
    </visual>
    <collision>
      <origin rpy="0 0 0" xyz="0.048 -0.02 0.8250000000000001"/>
      <geometry>
        <mesh filename="package://subwoofer_model/meshes/V1.02_Right_MidLimb.dae" scale="0.001 0.001 0.001"/>
      </geometry>
    </collision>
  </link>
  <joint name="front_right_midlimb_to_front_right_midlimb_servo" type="fixed">
    <parent link="front_right_midlimb_servo"/>
    <child link="front_right_midlimb"/>
    <origin rpy="0 0 -1.57075" xyz="0.009000000000000001 0.013000000000000001 -0.107"/>
  </joint>
  <link name="front_right_midlimb_cover">
    <inertial>
      <mass value="0.050"/>
      <inertia ixx="1e-3" ixy="0.0" ixz="0.0" iyy="1e-3" iyz="0.0" izz="1e-3"/>
    </inertial>
    <visual>
      <origin rpy="0 0 0" xyz="-0.256 -0.11 0.926"/>
      <geometry>
        <mesh filename="package://subwoofer_model/meshes/V1.02_Right_MidLimb_Cover.dae" scale="0.001 0.001 0.001"/>
      </geometry>
    </visual>
    <collision>
      <origin rpy="0 0 0" xyz="-0.256 -0.11 0.926"/>
      <geometry>
        <mesh filename="package://subwoofer_model/meshes/V1.02_Right_MidLimb_Cover.dae" scale="0.001 0.001 0.001"/>
      </geometry>
    </collision>
  </link>
  <joint name="front_right_midlimb_cover_to_front_right_midlimb" type="fixed">
    <parent link="front_right_midlimb"/>
    <child link="front_right_midlimb_cover"/>
    <origin rpy="0 0 0" xyz="0.0 0.0497 0.0"/>
  </joint>
  <link name="front_right_wrist_servo">
    <inertial>
      <mass value="0.050"/>
      <inertia ixx="1e-3" ixy="0.0" ixz="0.0" iyy="1e-3" iyz="0.0" izz="1e-3"/>
    </inertial>
    <visual>
      <origin rpy="0 3.1415 1.57075" xyz="0.043000000000000003 0.0 -0.01"/>
      <geometry>
        <mesh filename="package://subwoofer_model/meshes/Servo.dae" scale="0.001 0.001 0.001"/>
      </geometry>
    </visual>
    <collision>
      <origin rpy="0 3.1415 1.57075" xyz="0.043000000000000003 0.0 -0.01"/>
      <geometry>
        <mesh filename="package://subwoofer_model/meshes/Servo.dae" scale="0.001 0.001 0.001"/>
      </geometry>
    </collision>
  </link>
  <joint name="front_right_wrist_servo_to_front_right_midlimb" type="revolute">
    <parent link="front_right_midlimb"/>
    <child link="front_right_wrist_servo"/>
    <axis xyz="1 0 0"/>
    <limit effort="1000.0" lower="-1.1" upper="2.6" velocity="0.5"/>
    <origin rpy="0 0 1.57075" xyz="0.0 0.0 0.0"/>
    <dynamics damping="0.05" friction="0.05"/>
  </joint>
  <link name="front_right_wrist">
    <inertial>
      <mass value="0.050"/>
      <inertia ixx="1e-3" ixy="0.0" ixz="0.0" iyy="1e-3" iyz="0.0" izz="1e-3"/>
    </inertial>
    <visual>
      <origin rpy="0 1.57075 1.57075" xyz="-0.507 0.23500000000000001 0.148"/>
      <geometry>
        <mesh filename="package://subwoofer_model/meshes/V1.02_Right_Wrist.dae" scale="0.001 0.001 0.001"/>
      </geometry>
    </visual>
    <collision>
      <origin rpy="0 1.57075 1.57075" xyz="-0.507 0.23500000000000001 0.148"/>
      <geometry>
        <mesh filename="package://subwoofer_model/meshes/V1.02_Right_Wrist.dae" scale="0.001 0.001 0.001"/>
      </geometry>
    </collision>
  </link>
  <joint name="front_right_wrist_to_front_right_wrist_servo" type="fixed">
    <parent link="front_right_wrist_servo"/>
    <child link="front_right_wrist"/>
    <origin rpy="0 0 0" xyz="0.053 0.0 0.0"/>
  </joint>
  <link name="back_left_hip_servo">
    <inertial>
      <mass value="0.050"/>
      <inertia ixx="1e-3" ixy="0.0" ixz="0.0" iyy="1e-3" iyz="0.0" izz="1e-3"/>
    </inertial>
    <visual>
      <origin rpy="0 3.1415 1.57075" xyz="0.043000000000000003 0.0 -0.01"/>
      <geometry>
        <mesh filename="package://subwoofer_model/meshes/Servo.dae" scale="0.001 0.001 0.001"/>
      </geometry>
    </visual>
    <collision>
      <origin rpy="0 3.1415 1.57075" xyz="0.043000000000000003 0.0 -0.01"/>
      <geometry>
        <mesh filename="package://subwoofer_model/meshes/Servo.dae" scale="0.001 0.001 0.001"/>
      </geometry>
    </collision>
  </link>
  <joint name="back_left_hip_servo_to_back_inner_shoulder" type="revolute">
    <parent link="back_inner_shoulder"/>
    <child link="back_left_hip_servo"/>
    <axis xyz="1 0 0"/>
    <limit effort="1000.0" lower="-0.78" upper="0.78" velocity="0.5"/>
    <origin rpy="0 0 -1.57075" xyz="-0.037 0.0 0.007"/>
    <dynamics damping="0.05" friction="0.05"/>
  </joint>
  <link name="back_left_hip">
    <inertial>
      <mass value="0.050"/>
      <inertia ixx="1e-3" ixy="0.0" ixz="0.0" iyy="1e-3" iyz="0.0" izz="1e-3"/>
    </inertial>
    <visual>
      <origin rpy="0 0 0" xyz="0.003 -0.023 -0.026000000000000002"/>
      <geometry>
        <mesh filename="package://subwoofer_model/meshes/V1.02_Left_Hind_Limb.dae" scale="0.001 0.001 0.001"/>
      </geometry>
    </visual>
    <collision>
      <origin rpy="0 0 0" xyz="0.003 -0.023 -0.026000000000000002"/>
      <geometry>
        <mesh filename="package://subwoofer_model/meshes/V1.02_Left_Hind_Limb.dae" scale="0.001 0.001 0.001"/>
      </geometry>
    </collision>
  </link>
  <joint name="back_left_hip_to_back_left_hip_servo" type="fixed">
    <parent link="back_left_hip_servo"/>
    <child link="back_left_hip"/>
    <origin rpy="0 0 -1.57075" xyz="0.0272 -0.025 -0.01"/>
  </joint>
  <link name="back_left_midlimb_servo">
    <inertial>
      <mass value="0.050"/>
      <inertia ixx="1e-3" ixy="0.0" ixz="0.0" iyy="1e-3" iyz="0.0" izz="1e-3"/>
    </inertial>
    <visual>
      <origin rpy="0 3.1415 1.57075" xyz="0.043000000000000003 0.0 -0.01"/>
      <geometry>
        <mesh filename="package://subwoofer_model/meshes/Servo.dae" scale="0.001 0.001 0.001"/>
      </geometry>
    </visual>
    <collision>
      <origin rpy="0 3.1415 1.57075" xyz="0.043000000000000003 0.0 -0.01"/>
      <geometry>
        <mesh filename="package://subwoofer_model/meshes/Servo.dae" scale="0.001 0.001 0.001"/>
      </geometry>
    </collision>
  </link>
  <joint name="back_left_midlimb_servo_to_back_left_hip" type="revolute">
    <parent link="back_left_hip"/>
    <child link="back_left_midlimb_servo"/>
    <axis xyz="1 0 0"/>
    <limit effort="1000.0" lower="-1.57" upper="1.57" velocity="0.5"/>
    <origin rpy="0 0 0" xyz="0 0 0"/>
    <dynamics damping="0.05" friction="0.05"/>
  </joint>
  <link name="back_left_midlimb">
    <inertial>
      <mass value="0.050"/>
      <inertia ixx="1e-3" ixy="0.0" ixz="0.0" iyy="1e-3" iyz="0.0" izz="1e-3"/>
    </inertial>
    <visual>
      <origin rpy="0 3.1415 0" xyz="-0.048 -0.02 0.8250000000000001"/>
      <geometry>
        <mesh filename="package://subwoofer_model/meshes/V1.02_Left_MidLimb.dae" scale="0.001 0.001 0.001"/>
      </geometry>
    </visual>
    <collision>
      <origin rpy="0 3.1415 0" xyz="-0.048 -0.02 0.8250000000000001"/>
      <geometry>
        <mesh filename="package://subwoofer_model/meshes/V1.02_Left_MidLimb.dae" scale="0.001 0.001 0.001"/>
      </geometry>
    </collision>
  </link>
  <joint name="back_left_midlimb_to_back_left_midlimb_servo" type="fixed">
    <parent link="back_left_midlimb_servo"/>
    <child link="back_left_midlimb"/>
    <origin rpy="0 0 -1.57075" xyz="0.009000000000000001 -0.013000000000000001 -0.107"/>
  </joint>
  <link name="back_left_midlimb_cover">
    <inertial>
      <mass value="0.050"/>
      <inertia ixx="1e-3" ixy="0.0" ixz="0.0" iyy="1e-3" iyz="0.0" izz="1e-3"/>
    </inertial>
    <visual>
      <origin rpy="0 3.1415 0" xyz="0.256 -0.11 0.926"/>
      <geometry>
        <mesh filename="package://subwoofer_model/meshes/V1.02_Left_MidLimb_Cover.dae" scale="0.001 0.001 0.001"/>
      </geometry>
    </visual>
    <collision>
      <origin rpy="0 3.1415 0" xyz="0.256 -0.11 0.926"/>
      <geometry>
        <mesh filename="package://subwoofer_model/meshes/V1.02_Left_MidLimb_Cover.dae" scale="0.001 0.001 0.001"/>
      </geometry>
    </collision>
  </link>
  <joint name="back_left_midlimb_cover_to_back_left_midlimb" type="fixed">
    <parent link="back_left_midlimb"/>
    <child link="back_left_midlimb_cover"/>
    <origin rpy="0 0 0" xyz="0 0.0497 0"/>
  </joint>
  <link name="back_left_wrist_servo">
    <inertial>
      <mass value="0.050"/>
      <inertia ixx="1e-3" ixy="0.0" ixz="0.0" iyy="1e-3" iyz="0.0" izz="1e-3"/>
    </inertial>
    <visual>
      <origin rpy="0 3.1415 1.57075" xyz="0.043000000000000003 0.0 -0.01"/>
      <geometry>
        <mesh filename="package://subwoofer_model/meshes/Servo.dae" scale="0.001 0.001 0.001"/>
      </geometry>
    </visual>
    <collision>
      <origin rpy="0 3.1415 1.57075" xyz="0.043000000000000003 0.0 -0.01"/>
      <geometry>
        <mesh filename="package://subwoofer_model/meshes/Servo.dae" scale="0.001 0.001 0.001"/>
      </geometry>
    </collision>
  </link>
  <joint name="back_left_wrist_servo_to_back_left_midlimb" type="revolute">
    <parent link="back_left_midlimb"/>
    <child link="back_left_wrist_servo"/>
    <axis xyz="1 0 0"/>
    <limit effort="1000.0" lower="-2.6" upper="1.1" velocity="0.5"/>
    <origin rpy="0 0 1.57075" xyz="0 0 0"/>
    <dynamics damping="0.05" friction="0.05"/>
  </joint>
  <link name="back_left_wrist">
    <inertial>
      <mass value="0.050"/>
      <inertia ixx="1e-3" ixy="0.0" ixz="0.0" iyy="1e-3" iyz="0.0" izz="1e-3"/>
    </inertial>
    <visual>
      <origin rpy="0 1.57075 -1.57075" xyz="0.507 0.23500000000000001 0.148"/>
      <geometry>
        <mesh filename="package://subwoofer_model/meshes/V1.02_Left_Wrist.dae" scale="0.001 0.001 0.001"/>
      </geometry>
    </visual>
    <collision>
      <origin rpy="0 1.57075 -1.57075" xyz="0.507 0.23500000000000001 0.148"/>
      <geometry>
        <mesh filename="package://subwoofer_model/meshes/V1.02_Left_Wrist.dae" scale="0.001 0.001 0.001"/>
      </geometry>
    </collision>
  </link>
  <joint name="back_left_wrist_to_back_left_wrist_servo" type="fixed">
    <parent link="back_left_wrist_servo"/>
    <child link="back_left_wrist"/>
    <origin rpy="0 0 3.1415" xyz="0.053 0 0"/>
  </joint>
  <link name="back_right_hip_servo">
    <inertial>
      <mass value="0.050"/>
      <inertia ixx="1e-3" ixy="0.0" ixz="0.0" iyy="1e-3" iyz="0.0" izz="1e-3"/>
    </inertial>
    <visual>
      <origin rpy="0 3.1415 1.57075" xyz="0.043000000000000003 0.0 -0.01"/>
      <geometry>
        <mesh filename="package://subwoofer_model/meshes/Servo.dae" scale="0.001 0.001 0.001"/>
      </geometry>
    </visual>
    <collision>
      <origin rpy="0 3.1415 1.57075" xyz="0.043000000000000003 0.0 -0.01"/>
      <geometry>
        <mesh filename="package://subwoofer_model/meshes/Servo.dae" scale="0.001 0.001 0.001"/>
      </geometry>
    </collision>
  </link>
  <joint name="back_right_hip_servo_to_back_inner_shoulder" type="revolute">
    <parent link="back_inner_shoulder"/>
    <child link="back_right_hip_servo"/>
    <axis xyz="1 0 0"/>
    <limit effort="1000.0" lower="-0.78" upper="0.78" velocity="0.5"/>
    <origin rpy="0 0 -1.57075" xyz="0.037 0.0 0.007"/>
    <dynamics damping="0.05" friction="0.05"/>
  </joint>
  <link name="back_right_hip">
    <inertial>
      <mass value="0.050"/>
      <inertia ixx="1e-3" ixy="0.0" ixz="0.0" iyy="1e-3" iyz="0.0" izz="1e-3"/>
    </inertial>
    <visual>
      <origin rpy="3.1415 0 0" xyz="-0.12 0.10300000000000001 0.0282"/>
      <geometry>
        <mesh filename="package://subwoofer_model/meshes/V1.02_Right_Hind_Limb.dae" scale="0.001 0.001 0.001"/>
      </geometry>
    </visual>
    <collision>
      <origin rpy="3.1415 0 0" xyz="-0.12 0.10300000000000001 0.0282"/>
      <geometry>
        <mesh filename="package://subwoofer_model/meshes/V1.02_Right_Hind_Limb.dae" scale="0.001 0.001 0.001"/>
      </geometry>
    </collision>
  </link>
  <joint name="back_right_hip_to_back_right_hip_servo" type="fixed">
    <parent link="back_right_hip_servo"/>
    <child link="back_right_hip"/>
    <origin rpy="0 0 1.57075" xyz="0.0272 0.025 -0.01"/>
  </joint>
  <link name="back_right_midlimb_servo">
    <inertial>
      <mass value="0.050"/>
      <inertia ixx="1e-3" ixy="0.0" ixz="0.0" iyy="1e-3" iyz="0.0" izz="1e-3"/>
    </inertial>
    <visual>
      <origin rpy="0 3.1415 1.57075" xyz="0.043000000000000003 0.0 -0.01"/>
      <geometry>
        <mesh filename="package://subwoofer_model/meshes/Servo.dae" scale="0.001 0.001 0.001"/>
      </geometry>
    </visual>
    <collision>
      <origin rpy="0 3.1415 1.57075" xyz="0.043000000000000003 0.0 -0.01"/>
      <geometry>
        <mesh filename="package://subwoofer_model/meshes/Servo.dae" scale="0.001 0.001 0.001"/>
      </geometry>
    </collision>
  </link>
  <joint name="back_right_midlimb_servo_to_back_right_hip" type="revolute">
    <parent link="back_right_hip"/>
    <child link="back_right_midlimb_servo"/>
    <axis xyz="1 0 0"/>
    <limit effort="1000.0" lower="-1.57" upper="1.57" velocity="0.5"/>
    <origin rpy="0 0 0" xyz="0 0 0"/>
    <dynamics damping="0.05" friction="0.05"/>
  </joint>
  <link name="back_right_midlimb">
    <inertial>
      <mass value="0.050"/>
      <inertia ixx="1e-3" ixy="0.0" ixz="0.0" iyy="1e-3" iyz="0.0" izz="1e-3"/>
    </inertial>
    <visual>
      <origin rpy="0 0 0" xyz="0.048 -0.02 0.8250000000000001"/>
      <geometry>
        <mesh filename="package://subwoofer_model/meshes/V1.02_Right_MidLimb.dae" scale="0.001 0.001 0.001"/>
      </geometry>
    </visual>
    <collision>
      <origin rpy="0 0 0" xyz="0.048 -0.02 0.8250000000000001"/>
      <geometry>
        <mesh filename="package://subwoofer_model/meshes/V1.02_Right_MidLimb.dae" scale="0.001 0.001 0.001"/>
      </geometry>
    </collision>
  </link>
  <joint name="back_right_midlimb_to_back_right_midlimb_servo" type="fixed">
    <parent link="back_right_midlimb_servo"/>
    <child link="back_right_midlimb"/>
    <origin rpy="0 0 -1.57075" xyz="0.009000000000000001 0.013000000000000001 -0.107"/>
  </joint>
  <link name="back_right_midlimb_cover">
    <inertial>
      <mass value="0.050"/>
      <inertia ixx="1e-3" ixy="0.0" ixz="0.0" iyy="1e-3" iyz="0.0" izz="1e-3"/>
    </inertial>
    <visual>
      <origin rpy="0 0 0" xyz="-0.256 -0.11 0.926"/>
      <geometry>
        <mesh filename="package://subwoofer_model/meshes/V1.02_Right_MidLimb_Cover.dae" scale="0.001 0.001 0.001"/>
      </geometry>
    </visual>
    <collision>
      <origin rpy="0 0 0" xyz="-0.256 -0.11 0.926"/>
      <geometry>
        <mesh filename="package://subwoofer_model/meshes/V1.02_Right_MidLimb_Cover.dae" scale="0.001 0.001 0.001"/>
      </geometry>
    </collision>
  </link>
  <joint name="back_right_midlimb_cover_to_back_right_midlimb" type="fixed">
    <parent link="back_right_midlimb"/>
    <child link="back_right_midlimb_cover"/>
    <origin rpy="0 0 0" xyz="0.0 0.0497 0.0"/>
  </joint>
  <link name="back_right_wrist_servo">
    <inertial>
      <mass value="0.050"/>
      <inertia ixx="1e-3" ixy="0.0" ixz="0.0" iyy="1e-3" iyz="0.0" izz="1e-3"/>
    </inertial>
    <visual>
      <origin rpy="0 3.1415 1.57075" xyz="0.043000000000000003 0.0 -0.01"/>
      <geometry>
        <mesh filename="package://subwoofer_model/meshes/Servo.dae" scale="0.001 0.001 0.001"/>
      </geometry>
    </visual>
    <collision>
      <origin rpy="0 3.1415 1.57075" xyz="0.043000000000000003 0.0 -0.01"/>
      <geometry>
        <mesh filename="package://subwoofer_model/meshes/Servo.dae" scale="0.001 0.001 0.001"/>
      </geometry>
    </collision>
  </link>
  <joint name="back_right_wrist_servo_to_back_right_midlimb" type="revolute">
    <parent link="back_right_midlimb"/>
    <child link="back_right_wrist_servo"/>
    <axis xyz="1 0 0"/>
    <limit effort="1000.0" lower="-1.1" upper="2.6" velocity="0.5"/>
    <origin rpy="0 0 1.57075" xyz="0.0 0.0 0.0"/>
    <dynamics damping="0.05" friction="0.05"/>
  </joint>
  <link name="back_right_wrist">
    <inertial>
      <mass value="0.050"/>
      <inertia ixx="1e-3" ixy="0.0" ixz="0.0" iyy="1e-3" iyz="0.0" izz="1e-3"/>
    </inertial>
    <visual>
      <origin rpy="0 1.57075 1.57075" xyz="-0.507 0.23500000000000001 0.148"/>
      <geometry>
        <mesh filename="package://subwoofer_model/meshes/V1.02_Right_Wrist.dae" scale="0.001 0.001 0.001"/>
      </geometry>
    </visual>
    <collision>
      <origin rpy="0 1.57075 1.57075" xyz="-0.507 0.23500000000000001 0.148"/>
      <geometry>
        <mesh filename="package://subwoofer_model/meshes/V1.02_Right_Wrist.dae" scale="0.001 0.001 0.001"/>
      </geometry>
    </collision>
  </link>
  <joint name="back_right_wrist_to_back_right_wrist_servo" type="fixed">
    <parent link="back_right_wrist_servo"/>
    <child link="back_right_wrist"/>
    <origin rpy="0 0 0" xyz="0.053 0.0 0.0"/>
  </joint>
</robot>
