<sdf version='1.9'>
  <model name='Subwoofer'>
    <joint name='world_joint' type='fixed'>
      <pose relative_to='__model__'>0 0 0 0 0 0</pose>
      <parent>world</parent>
      <child>base_link</child>
    </joint>
    <link name='base_link'>
      <pose relative_to='world_joint'>0 0 0 0 0 0</pose>
      <inertial>
        <pose>-7.885106708985487e-19 -0.0007272727272727292 0.008136363636363638 0 0 0</pose>
        <mass>0.55000000000000004</mass>
        <inertia>
          <ixx>0.014998111363636371</ixx>
          <ixy>2.8504660752982543e-20</ixy>
          <ixz>5.964652008574368e-22</ixz>
          <iyy>0.011427527272727269</iyy>
          <iyz>5.289545454545456e-05</iyz>
          <izz>0.015153784090909089</izz>
        </inertia>
      </inertial>
      <collision name='base_link_collision'>
        <pose>-0.1506 -0.1519 -0.4 0 0 0</pose>
        <geometry>
          <mesh>
            <scale>0.001 0.001 0.001</scale>
            <uri>model://subwoofer_model/meshes/V1.02_Chassis_BasePlate_RPi4.stl</uri>
          </mesh>
        </geometry>
      </collision>
      <collision name='base_link_fixed_joint_lump__back_inner_shoulder_collision_1'>
        <pose>-0.116 -0.064 0.477 3.1415 0 0</pose>
        <geometry>
          <mesh>
            <scale>0.001 0.001 0.001</scale>
            <uri>model://subwoofer_model/meshes/V1.02_Rear_Inner_Shoulder.stl</uri>
          </mesh>
        </geometry>
      </collision>
      <collision name='base_link_fixed_joint_lump__back_outer_shoulder_collision_2'>
        <pose>0.117 -0.064 -0.46 0 0 3.1415</pose>
        <geometry>
          <mesh>
            <scale>0.001 0.001 0.001</scale>
            <uri>model://subwoofer_model/meshes/V1.02_Rear_Outer_Shoulder.stl</uri>
          </mesh>
        </geometry>
      </collision>
      <collision name='base_link_fixed_joint_lump__rear_chassis_collision_3'>
        <pose>0.2487 0.107 0.39 0 1.570796326794897 1.57075</pose>
        <geometry>
          <mesh>
            <scale>0.001 0.001 0.001</scale>
            <uri>model://subwoofer_model/meshes/V1.02_Cover_Rear_Plain.stl</uri>
          </mesh>
        </geometry>
      </collision>
      <collision name='base_link_fixed_joint_lump__bottom_chassis_collision_4'>
        <pose>1.004 1.015 1.264 1.57075 0 -1.57075</pose>
        <geometry>
          <mesh>
            <scale>0.001 0.001 0.001</scale>
            <uri>model://subwoofer_model/meshes/V1.02_Cover_Bottom.stl</uri>
          </mesh>
        </geometry>
      </collision>
      <collision name='base_link_fixed_joint_lump__top_chassis_collision_5'>
        <pose>1.004 -1.016 -1.248 -1.57075 0 1.57075</pose>
        <geometry>
          <mesh>
            <scale>0.001 0.001 0.001</scale>
            <uri>model://subwoofer_model/meshes/V1.02_Cover_Top.stl</uri>
          </mesh>
        </geometry>
      </collision>
      <collision name='base_link_fixed_joint_lump__front_inner_shoulder_collision_6'>
        <pose>-0.034 0.063 0.043 1.57075 -6.776263578034403e-21 3.1415</pose>
        <geometry>
          <mesh>
            <scale>0.001 0.001 0.001</scale>
            <uri>model://subwoofer_model/meshes/V1.02_Front_Inner_Shoulder.stl</uri>
          </mesh>
        </geometry>
      </collision>
      <collision name='base_link_fixed_joint_lump__front_outer_shoulder_collision_7'>
        <pose>-0.1155 0.121 0.477 3.141592653589793 9.265358979305728e-05 -9.265358979305726e-05</pose>
        <geometry>
          <mesh>
            <scale>0.001 0.001 0.001</scale>
            <uri>model://subwoofer_model/meshes/V1.02_Front_Outer_Shoulder.stl</uri>
          </mesh>
        </geometry>
      </collision>
      <collision name='base_link_fixed_joint_lump__left_chassis_collision_8'>
        <pose>-0.054 -0.0005000000000000004 0.0105 0 -1.570796326794897 3.1415</pose>
        <geometry>
          <mesh>
            <scale>0.001 0.001 0.001</scale>
            <uri>model://subwoofer_model/meshes/V1.02_Chassis_Left_Side.stl</uri>
          </mesh>
        </geometry>
      </collision>
      <collision name='base_link_fixed_joint_lump__nose_chassis_collision_9'>
        <pose>0.142 0.494 0.5125000000000001 3.1415 -6.776263578034403e-21 1.57075</pose>
        <geometry>
          <mesh>
            <scale>0.001 0.001 0.001</scale>
            <uri>model://subwoofer_model/meshes/V1.02_Cover_Nose.stl</uri>
          </mesh>
        </geometry>
      </collision>
      <collision name='base_link_fixed_joint_lump__right_chassis_collision_10'>
        <pose>0.054 -0.0005000000000000004 0.0105 0 -1.570796326794897 0</pose>
        <geometry>
          <mesh>
            <scale>0.001 0.001 0.001</scale>
            <uri>model://subwoofer_model/meshes/V1.02_Chassis_Right_Side.stl</uri>
          </mesh>
        </geometry>
      </collision>
      <visual name='base_link_visual'>
        <pose>-0.1506 -0.1519 -0.4 0 0 0</pose>
        <geometry>
          <mesh>
            <scale>0.001 0.001 0.001</scale>
            <uri>model://subwoofer_model/meshes/V1.02_Chassis_BasePlate_RPi4.stl</uri>
          </mesh>
        </geometry>
      </visual>
      <visual name='base_link_fixed_joint_lump__back_inner_shoulder_visual_1'>
        <pose>-0.116 -0.064 0.477 3.1415 0 0</pose>
        <geometry>
          <mesh>
            <scale>0.001 0.001 0.001</scale>
            <uri>model://subwoofer_model/meshes/V1.02_Rear_Inner_Shoulder.stl</uri>
          </mesh>
        </geometry>
      </visual>
      <visual name='base_link_fixed_joint_lump__back_outer_shoulder_visual_2'>
        <pose>0.117 -0.064 -0.46 0 0 3.1415</pose>
        <geometry>
          <mesh>
            <scale>0.001 0.001 0.001</scale>
            <uri>model://subwoofer_model/meshes/V1.02_Rear_Outer_Shoulder.stl</uri>
          </mesh>
        </geometry>
      </visual>
      <visual name='base_link_fixed_joint_lump__rear_chassis_visual_3'>
        <pose>0.2487 0.107 0.39 0 1.570796326794897 1.57075</pose>
        <geometry>
          <mesh>
            <scale>0.001 0.001 0.001</scale>
            <uri>model://subwoofer_model/meshes/V1.02_Cover_Rear_Plain.stl</uri>
          </mesh>
        </geometry>
      </visual>
      <visual name='base_link_fixed_joint_lump__bottom_chassis_visual_4'>
        <pose>1.004 1.015 1.264 1.57075 0 -1.57075</pose>
        <geometry>
          <mesh>
            <scale>0.001 0.001 0.001</scale>
            <uri>model://subwoofer_model/meshes/V1.02_Cover_Bottom.stl</uri>
          </mesh>
        </geometry>
      </visual>
      <visual name='base_link_fixed_joint_lump__top_chassis_visual_5'>
        <pose>1.004 -1.016 -1.248 -1.57075 0 1.57075</pose>
        <geometry>
          <mesh>
            <scale>0.001 0.001 0.001</scale>
            <uri>model://subwoofer_model/meshes/V1.02_Cover_Top.stl</uri>
          </mesh>
        </geometry>
      </visual>
      <visual name='base_link_fixed_joint_lump__front_inner_shoulder_visual_6'>
        <pose>-0.034 0.063 0.043 1.57075 -6.776263578034403e-21 3.1415</pose>
        <geometry>
          <mesh>
            <scale>0.001 0.001 0.001</scale>
            <uri>model://subwoofer_model/meshes/V1.02_Front_Inner_Shoulder.stl</uri>
          </mesh>
        </geometry>
      </visual>
      <visual name='base_link_fixed_joint_lump__front_outer_shoulder_visual_7'>
        <pose>-0.1155 0.121 0.477 3.141592653589793 9.265358979305728e-05 -9.265358979305726e-05</pose>
        <geometry>
          <mesh>
            <scale>0.001 0.001 0.001</scale>
            <uri>model://subwoofer_model/meshes/V1.02_Front_Outer_Shoulder.stl</uri>
          </mesh>
        </geometry>
      </visual>
      <visual name='base_link_fixed_joint_lump__left_chassis_visual_8'>
        <pose>-0.054 -0.0005000000000000004 0.0105 0 -1.570796326794897 3.1415</pose>
        <geometry>
          <mesh>
            <scale>0.001 0.001 0.001</scale>
            <uri>model://subwoofer_model/meshes/V1.02_Chassis_Left_Side.stl</uri>
          </mesh>
        </geometry>
      </visual>
      <visual name='base_link_fixed_joint_lump__nose_chassis_visual_9'>
        <pose>0.142 0.494 0.5125000000000001 3.1415 -6.776263578034403e-21 1.57075</pose>
        <geometry>
          <mesh>
            <scale>0.001 0.001 0.001</scale>
            <uri>model://subwoofer_model/meshes/V1.02_Cover_Nose.stl</uri>
          </mesh>
        </geometry>
      </visual>
      <visual name='base_link_fixed_joint_lump__right_chassis_visual_10'>
        <pose>0.054 -0.0005000000000000004 0.0105 0 -1.570796326794897 0</pose>
        <geometry>
          <mesh>
            <scale>0.001 0.001 0.001</scale>
            <uri>model://subwoofer_model/meshes/V1.02_Chassis_Right_Side.stl</uri>
          </mesh>
        </geometry>
      </visual>
    </link>
    <joint name='back_left_hip_servo_to_back_inner_shoulder' type='revolute'>
      <pose relative_to='base_link'>-0.037 -0.066 0.017 0 0 -1.57075</pose>
      <parent>base_link</parent>
      <child>back_left_hip_servo</child>
      <axis>
        <xyz>1 0 0</xyz>
        <limit>
          <lower>-0.78000000000000003</lower>
          <upper>0.78000000000000003</upper>
          <effort>1000</effort>
          <velocity>0.5</velocity>
        </limit>
        <dynamics>
          <damping>0.050000000000000003</damping>
          <friction>0.050000000000000003</friction>
          <spring_reference>0</spring_reference>
          <spring_stiffness>0</spring_stiffness>
        </dynamics>
      </axis>
    </joint>
    <link name='back_left_hip_servo'>
      <pose relative_to='back_left_hip_servo_to_back_inner_shoulder'>0 0 0 0 0 0</pose>
      <inertial>
        <pose>0.0136 -0.0125 -0.005 0 0 0</pose>
        <mass>0.10000000000000001</mass>
        <inertia>
          <ixx>0.002018125</ixx>
          <ixy>1.7e-05</ixy>
          <ixz>6.7999999999999984e-06</ixz>
          <iyy>0.0020209960000000002</iyy>
          <iyz>-6.2499999999999986e-06</iyz>
          <izz>0.0020341209999999998</izz>
        </inertia>
      </inertial>
      <collision name='back_left_hip_servo_collision'>
        <pose>0.043 0 -0.01 3.141592653589793 9.26535897930573e-05 -1.570842653589793</pose>
        <geometry>
          <mesh>
            <scale>0.001 0.001 0.001</scale>
            <uri>model://subwoofer_model/meshes/Servo.stl</uri>
          </mesh>
        </geometry>
      </collision>
      <collision name='back_left_hip_servo_fixed_joint_lump__back_left_hip_collision_1'>
        <pose>0.004200139005065613 -0.02800106551306298 -0.036 0 0 -1.57075</pose>
        <geometry>
          <mesh>
            <scale>0.001 0.001 0.001</scale>
            <uri>model://subwoofer_model/meshes/V1.02_Left_Hind_Limb.stl</uri>
          </mesh>
        </geometry>
      </collision>
      <visual name='back_left_hip_servo_visual'>
        <pose>0.043 0 -0.01 3.141592653589793 9.26535897930573e-05 -1.570842653589793</pose>
        <geometry>
          <mesh>
            <scale>0.001 0.001 0.001</scale>
            <uri>model://subwoofer_model/meshes/Servo.stl</uri>
          </mesh>
        </geometry>
      </visual>
      <visual name='back_left_hip_servo_fixed_joint_lump__back_left_hip_visual_1'>
        <pose>0.004200139005065613 -0.02800106551306298 -0.036 0 0 -1.57075</pose>
        <geometry>
          <mesh>
            <scale>0.001 0.001 0.001</scale>
            <uri>model://subwoofer_model/meshes/V1.02_Left_Hind_Limb.stl</uri>
          </mesh>
        </geometry>
      </visual>
    </link>
    <joint name='back_left_midlimb_servo_to_back_left_hip' type='revolute'>
      <pose relative_to='back_left_hip_servo'>0.0272 -0.025 -0.01 0 0 -1.57075</pose>
      <parent>back_left_hip_servo</parent>
      <child>back_left_midlimb_servo</child>
      <axis>
        <xyz>1 0 0</xyz>
        <limit>
          <lower>-1.5700000000000001</lower>
          <upper>1.5700000000000001</upper>
          <effort>1000</effort>
          <velocity>0.5</velocity>
        </limit>
        <dynamics>
          <damping>0.050000000000000003</damping>
          <friction>0.050000000000000003</friction>
          <spring_reference>0</spring_reference>
          <spring_stiffness>0</spring_stiffness>
        </dynamics>
      </axis>
    </joint>
    <link name='back_left_midlimb_servo'>
      <pose relative_to='back_left_midlimb_servo_to_back_left_hip'>0 0 0 0 0 0</pose>
      <inertial>
        <pose>0.02256666664888921 -0.008665899186098157 -0.07133333333333333 0 0 0</pose>
        <mass>0.14999999999999999</mass>
        <inertia>
          <ixx>0.0033872656691186359</ixx>
          <ixy>1.4664173577100751e-05</ixy>
          <ixz>0.0001207316665715573</ixz>
          <iyy>0.0034815796664739592</iyy>
          <iyz>-4.6362560645625107e-05</iyz>
          <izz>0.003105578668925928</izz>
        </inertia>
      </inertial>
      <collision name='back_left_midlimb_servo_collision'>
        <pose>0.043 0 -0.01 3.141592653589793 9.26535897930573e-05 -1.570842653589793</pose>
        <geometry>
          <mesh>
            <scale>0.001 0.001 0.001</scale>
            <uri>model://subwoofer_model/meshes/Servo.stl</uri>
          </mesh>
        </geometry>
      </collision>
      <collision name='back_left_midlimb_servo_fixed_joint_lump__back_left_midlimb_collision_1'>
        <pose>-0.01100222366469251 0.03499907341259428 0.7180000000000001 -3.141592653589793 9.26535897930573e-05 1.570842653589793</pose>
        <geometry>
          <mesh>
            <scale>0.001 0.001 0.001</scale>
            <uri>model://subwoofer_model/meshes/V1.02_Left_MidLimb.stl</uri>
          </mesh>
        </geometry>
      </collision>
      <collision name='back_left_midlimb_servo_fixed_joint_lump__back_left_midlimb_cover_collision_2'>
        <pose>-0.05128814027580373 -0.2690027932310213 0.8190000000000001 -3.141592653589793 9.26535897930573e-05 1.570842653589793</pose>
        <geometry>
          <mesh>
            <scale>0.001 0.001 0.001</scale>
            <uri>model://subwoofer_model/meshes/V1.02_Left_MidLimb_Cover.stl</uri>
          </mesh>
        </geometry>
      </collision>
      <visual name='back_left_midlimb_servo_visual'>
        <pose>0.043 0 -0.01 3.141592653589793 9.26535897930573e-05 -1.570842653589793</pose>
        <geometry>
          <mesh>
            <scale>0.001 0.001 0.001</scale>
            <uri>model://subwoofer_model/meshes/Servo.stl</uri>
          </mesh>
        </geometry>
      </visual>
      <visual name='back_left_midlimb_servo_fixed_joint_lump__back_left_midlimb_visual_1'>
        <pose>-0.01100222366469251 0.03499907341259428 0.7180000000000001 -3.141592653589793 9.26535897930573e-05 1.570842653589793</pose>
        <geometry>
          <mesh>
            <scale>0.001 0.001 0.001</scale>
            <uri>model://subwoofer_model/meshes/V1.02_Left_MidLimb.stl</uri>
          </mesh>
        </geometry>
      </visual>
      <visual name='back_left_midlimb_servo_fixed_joint_lump__back_left_midlimb_cover_visual_2'>
        <pose>-0.05128814027580373 -0.2690027932310213 0.8190000000000001 -3.141592653589793 9.26535897930573e-05 1.570842653589793</pose>
        <geometry>
          <mesh>
            <scale>0.001 0.001 0.001</scale>
            <uri>model://subwoofer_model/meshes/V1.02_Left_MidLimb_Cover.stl</uri>
          </mesh>
        </geometry>
      </visual>
    </link>
    <joint name='back_left_wrist_servo_to_back_left_midlimb' type='revolute'>
      <pose relative_to='back_left_midlimb_servo'>0.009000000000000001 -0.013 -0.107 0 0 0</pose>
      <parent>back_left_midlimb_servo</parent>
      <child>back_left_wrist_servo</child>
      <axis>
        <xyz>1 0 0</xyz>
        <limit>
          <lower>-2.6000000000000001</lower>
          <upper>1.1000000000000001</upper>
          <effort>1000</effort>
          <velocity>0.5</velocity>
        </limit>
        <dynamics>
          <damping>0.050000000000000003</damping>
          <friction>0.050000000000000003</friction>
          <spring_reference>0</spring_reference>
          <spring_stiffness>0</spring_stiffness>
        </dynamics>
      </axis>
    </joint>
    <link name='back_left_wrist_servo'>
      <pose relative_to='back_left_wrist_servo_to_back_left_midlimb'>0 0 0 0 0 0</pose>
      <inertial>
        <pose>0.0265 0 0 0 0 0</pose>
        <mass>0.10000000000000001</mass>
        <inertia>
          <ixx>0.002</ixx>
          <ixy>1.323488980084844e-23</ixy>
          <ixz>0</ixz>
          <iyy>0.0020702250000000002</iyy>
          <iyz>0</iyz>
          <izz>0.0020702250000000002</izz>
        </inertia>
      </inertial>
      <collision name='back_left_wrist_servo_collision'>
        <pose>0.043 0 -0.01 3.141592653589793 9.26535897930573e-05 -1.570842653589793</pose>
        <geometry>
          <mesh>
            <scale>0.001 0.001 0.001</scale>
            <uri>model://subwoofer_model/meshes/Servo.stl</uri>
          </mesh>
        </geometry>
      </collision>
      <collision name='back_left_wrist_servo_fixed_joint_lump__back_left_wrist_collision_1'>
        <pose>-0.4540217714173519 -0.2349530236213414 0.148 0 1.570796326794897 1.57075</pose>
        <geometry>
          <mesh>
            <scale>0.001 0.001 0.001</scale>
            <uri>model://subwoofer_model/meshes/V1.02_Left_Wrist.stl</uri>
          </mesh>
        </geometry>
      </collision>
      <visual name='back_left_wrist_servo_visual'>
        <pose>0.043 0 -0.01 3.141592653589793 9.26535897930573e-05 -1.570842653589793</pose>
        <geometry>
          <mesh>
            <scale>0.001 0.001 0.001</scale>
            <uri>model://subwoofer_model/meshes/Servo.stl</uri>
          </mesh>
        </geometry>
      </visual>
      <visual name='back_left_wrist_servo_fixed_joint_lump__back_left_wrist_visual_1'>
        <pose>-0.4540217714173519 -0.2349530236213414 0.148 0 1.570796326794897 1.57075</pose>
        <geometry>
          <mesh>
            <scale>0.001 0.001 0.001</scale>
            <uri>model://subwoofer_model/meshes/V1.02_Left_Wrist.stl</uri>
          </mesh>
        </geometry>
      </visual>
    </link>
    <joint name='back_right_hip_servo_to_back_inner_shoulder' type='revolute'>
      <pose relative_to='base_link'>0.037 -0.066 0.017 0 0 -1.57075</pose>
      <parent>base_link</parent>
      <child>back_right_hip_servo</child>
      <axis>
        <xyz>1 0 0</xyz>
        <limit>
          <lower>-0.78000000000000003</lower>
          <upper>0.78000000000000003</upper>
          <effort>1000</effort>
          <velocity>0.5</velocity>
        </limit>
        <dynamics>
          <damping>0.050000000000000003</damping>
          <friction>0.050000000000000003</friction>
          <spring_reference>0</spring_reference>
          <spring_stiffness>0</spring_stiffness>
        </dynamics>
      </axis>
    </joint>
    <link name='back_right_hip_servo'>
      <pose relative_to='back_right_hip_servo_to_back_inner_shoulder'>0 0 0 0 0 0</pose>
      <inertial>
        <pose>0.0136 0.0125 -0.005 0 0 0</pose>
        <mass>0.10000000000000001</mass>
        <inertia>
          <ixx>0.002018125</ixx>
          <ixy>-1.7e-05</ixy>
          <ixz>6.7999999999999984e-06</ixz>
          <iyy>0.0020209960000000002</iyy>
          <iyz>6.2499999999999986e-06</iyz>
          <izz>0.0020341209999999998</izz>
        </inertia>
      </inertial>
      <collision name='back_right_hip_servo_collision'>
        <pose>0.043 0 -0.01 3.141592653589793 9.26535897930573e-05 -1.570842653589793</pose>
        <geometry>
          <mesh>
            <scale>0.001 0.001 0.001</scale>
            <uri>model://subwoofer_model/meshes/Servo.stl</uri>
          </mesh>
        </geometry>
      </collision>
      <collision name='back_right_hip_servo_fixed_joint_lump__back_right_hip_collision_1'>
        <pose>-0.07580555910485774 -0.09499522821135706 0.0182 3.1415 -6.776263578034403e-21 1.57075</pose>
        <geometry>
          <mesh>
            <scale>0.001 0.001 0.001</scale>
            <uri>model://subwoofer_model/meshes/V1.02_Right_Hind_Limb.stl</uri>
          </mesh>
        </geometry>
      </collision>
      <visual name='back_right_hip_servo_visual'>
        <pose>0.043 0 -0.01 3.141592653589793 9.26535897930573e-05 -1.570842653589793</pose>
        <geometry>
          <mesh>
            <scale>0.001 0.001 0.001</scale>
            <uri>model://subwoofer_model/meshes/Servo.stl</uri>
          </mesh>
        </geometry>
      </visual>
      <visual name='back_right_hip_servo_fixed_joint_lump__back_right_hip_visual_1'>
        <pose>-0.07580555910485774 -0.09499522821135706 0.0182 3.1415 -6.776263578034403e-21 1.57075</pose>
        <geometry>
          <mesh>
            <scale>0.001 0.001 0.001</scale>
            <uri>model://subwoofer_model/meshes/V1.02_Right_Hind_Limb.stl</uri>
          </mesh>
        </geometry>
      </visual>
    </link>
    <joint name='back_right_midlimb_servo_to_back_right_hip' type='revolute'>
      <pose relative_to='back_right_hip_servo'>0.0272 0.025 -0.01 0 0 1.57075</pose>
      <parent>back_right_hip_servo</parent>
      <child>back_right_midlimb_servo</child>
      <axis>
        <xyz>1 0 0</xyz>
        <limit>
          <lower>-1.5700000000000001</lower>
          <upper>1.5700000000000001</upper>
          <effort>1000</effort>
          <velocity>0.5</velocity>
        </limit>
        <dynamics>
          <damping>0.050000000000000003</damping>
          <friction>0.050000000000000003</friction>
          <spring_reference>0</spring_reference>
          <spring_stiffness>0</spring_stiffness>
        </dynamics>
      </axis>
    </joint>
    <link name='back_right_midlimb_servo'>
      <pose relative_to='back_right_midlimb_servo_to_back_right_hip'>0 0 0 0 0 0</pose>
      <inertial>
        <pose>0.02256666664888921 0.008667434147235179 -0.07133333333333333 0 0 0</pose>
        <mass>0.14999999999999999</mass>
        <inertia>
          <ixx>0.0033872676645681139</ixx>
          <ixy>-1.467249306645523e-05</ixy>
          <ixz>0.0001207316665715573</ixz>
          <iyy>0.0034815796664739592</iyy>
          <iyz>4.6370772687708167e-05</iyz>
          <izz>0.003105580664375406</izz>
        </inertia>
      </inertial>
      <collision name='back_right_midlimb_servo_collision'>
        <pose>0.043 0 -0.01 3.141592653589793 9.26535897930573e-05 -1.570842653589793</pose>
        <geometry>
          <mesh>
            <scale>0.001 0.001 0.001</scale>
            <uri>model://subwoofer_model/meshes/Servo.stl</uri>
          </mesh>
        </geometry>
      </collision>
      <collision name='back_right_midlimb_servo_fixed_joint_lump__back_right_midlimb_collision_1'>
        <pose>-0.01099777629238405 -0.03500092648438947 0.7180000000000001 0 0 -1.57075</pose>
        <geometry>
          <mesh>
            <scale>0.001 0.001 0.001</scale>
            <uri>model://subwoofer_model/meshes/V1.02_Right_MidLimb.stl</uri>
          </mesh>
        </geometry>
      </collision>
      <collision name='back_right_midlimb_servo_fixed_joint_lump__back_right_midlimb_cover_collision_2'>
        <pose>-0.05131185959478208 0.2689972062195588 0.8190000000000001 0 0 -1.57075</pose>
        <geometry>
          <mesh>
            <scale>0.001 0.001 0.001</scale>
            <uri>model://subwoofer_model/meshes/V1.02_Right_MidLimb_Cover.stl</uri>
          </mesh>
        </geometry>
      </collision>
      <visual name='back_right_midlimb_servo_visual'>
        <pose>0.043 0 -0.01 3.141592653589793 9.26535897930573e-05 -1.570842653589793</pose>
        <geometry>
          <mesh>
            <scale>0.001 0.001 0.001</scale>
            <uri>model://subwoofer_model/meshes/Servo.stl</uri>
          </mesh>
        </geometry>
      </visual>
      <visual name='back_right_midlimb_servo_fixed_joint_lump__back_right_midlimb_visual_1'>
        <pose>-0.01099777629238405 -0.03500092648438947 0.7180000000000001 0 0 -1.57075</pose>
        <geometry>
          <mesh>
            <scale>0.001 0.001 0.001</scale>
            <uri>model://subwoofer_model/meshes/V1.02_Right_MidLimb.stl</uri>
          </mesh>
        </geometry>
      </visual>
      <visual name='back_right_midlimb_servo_fixed_joint_lump__back_right_midlimb_cover_visual_2'>
        <pose>-0.05131185959478208 0.2689972062195588 0.8190000000000001 0 0 -1.57075</pose>
        <geometry>
          <mesh>
            <scale>0.001 0.001 0.001</scale>
            <uri>model://subwoofer_model/meshes/V1.02_Right_MidLimb_Cover.stl</uri>
          </mesh>
        </geometry>
      </visual>
    </link>
    <joint name='back_right_wrist_servo_to_back_right_midlimb' type='revolute'>
      <pose relative_to='back_right_midlimb_servo'>0.009000000000000001 0.013 -0.107 0 0 0</pose>
      <parent>back_right_midlimb_servo</parent>
      <child>back_right_wrist_servo</child>
      <axis>
        <xyz>1 0 0</xyz>
        <limit>
          <lower>-1.1000000000000001</lower>
          <upper>2.6000000000000001</upper>
          <effort>1000</effort>
          <velocity>0.5</velocity>
        </limit>
        <dynamics>
          <damping>0.050000000000000003</damping>
          <friction>0.050000000000000003</friction>
          <spring_reference>0</spring_reference>
          <spring_stiffness>0</spring_stiffness>
        </dynamics>
      </axis>
    </joint>
    <link name='back_right_wrist_servo'>
      <pose relative_to='back_right_wrist_servo_to_back_right_midlimb'>0 0 0 0 0 0</pose>
      <inertial>
        <pose>0.0265 0 0 0 0 0</pose>
        <mass>0.10000000000000001</mass>
        <inertia>
          <ixx>0.002</ixx>
          <ixy>0</ixy>
          <ixz>0</ixz>
          <iyy>0.0020702250000000002</iyy>
          <iyz>0</iyz>
          <izz>0.0020702250000000002</izz>
        </inertia>
      </inertial>
      <collision name='back_right_wrist_servo_collision'>
        <pose>0.043 0 -0.01 3.141592653589793 9.26535897930573e-05 -1.570842653589793</pose>
        <geometry>
          <mesh>
            <scale>0.001 0.001 0.001</scale>
            <uri>model://subwoofer_model/meshes/Servo.stl</uri>
          </mesh>
        </geometry>
      </collision>
      <collision name='back_right_wrist_servo_fixed_joint_lump__back_right_wrist_collision_1'>
        <pose>-0.454 0.235 0.148 0 1.570796326794897 1.57075</pose>
        <geometry>
          <mesh>
            <scale>0.001 0.001 0.001</scale>
            <uri>model://subwoofer_model/meshes/Right_Wrist.dae</uri>
          </mesh>
        </geometry>
      </collision>
      <visual name='back_right_wrist_servo_visual'>
        <pose>0.043 0 -0.01 3.141592653589793 9.26535897930573e-05 -1.570842653589793</pose>
        <geometry>
          <mesh>
            <scale>0.001 0.001 0.001</scale>
            <uri>model://subwoofer_model/meshes/Servo.stl</uri>
          </mesh>
        </geometry>
      </visual>
      <visual name='back_right_wrist_servo_fixed_joint_lump__back_right_wrist_visual_1'>
        <pose>-0.454 0.235 0.148 0 1.570796326794897 1.57075</pose>
        <geometry>
          <mesh>
            <scale>0.001 0.001 0.001</scale>
            <uri>model://subwoofer_model/meshes/Right_Wrist.dae</uri>
          </mesh>
        </geometry>
      </visual>
    </link>
    <joint name='front_left_hip_servo_to_front_outer_shoulder' type='revolute'>
      <pose relative_to='base_link'>-0.037 0.119 0.017 0 0 -1.57075</pose>
      <parent>base_link</parent>
      <child>front_left_hip_servo</child>
      <axis>
        <xyz>1 0 0</xyz>
        <limit>
          <lower>-0.78000000000000003</lower>
          <upper>0.78000000000000003</upper>
          <effort>1000</effort>
          <velocity>0.5</velocity>
        </limit>
        <dynamics>
          <damping>0.050000000000000003</damping>
          <friction>0.050000000000000003</friction>
          <spring_reference>0</spring_reference>
          <spring_stiffness>0</spring_stiffness>
        </dynamics>
      </axis>
    </joint>
    <link name='front_left_hip_servo'>
      <pose relative_to='front_left_hip_servo_to_front_outer_shoulder'>0 0 0 0 0 0</pose>
      <inertial>
        <pose>0.0136 -0.0125 -0.005 0 0 0</pose>
        <mass>0.10000000000000001</mass>
        <inertia>
          <ixx>0.002018125</ixx>
          <ixy>1.7e-05</ixy>
          <ixz>6.7999999999999984e-06</ixz>
          <iyy>0.0020209960000000002</iyy>
          <iyz>-6.2499999999999986e-06</iyz>
          <izz>0.0020341209999999998</izz>
        </inertia>
      </inertial>
      <collision name='front_left_hip_servo_collision'>
        <pose>0.043 0 -0.01 3.141592653589793 9.26535897930573e-05 -1.570842653589793</pose>
        <geometry>
          <mesh>
            <scale>0.001 0.001 0.001</scale>
            <uri>model://subwoofer_model/meshes/Servo.stl</uri>
          </mesh>
        </geometry>
      </collision>
      <collision name='front_left_hip_servo_fixed_joint_lump__front_left_hip_collision_1'>
        <pose>0.004200139005065613 -0.02800106551306298 -0.036 0 0 -1.57075</pose>
        <geometry>
          <mesh>
            <scale>0.001 0.001 0.001</scale>
            <uri>model://subwoofer_model/meshes/V1.02_Left_Hind_Limb.stl</uri>
          </mesh>
        </geometry>
      </collision>
      <visual name='front_left_hip_servo_visual'>
        <pose>0.043 0 -0.01 3.141592653589793 9.26535897930573e-05 -1.570842653589793</pose>
        <geometry>
          <mesh>
            <scale>0.001 0.001 0.001</scale>
            <uri>model://subwoofer_model/meshes/Servo.stl</uri>
          </mesh>
        </geometry>
      </visual>
      <visual name='front_left_hip_servo_fixed_joint_lump__front_left_hip_visual_1'>
        <pose>0.004200139005065613 -0.02800106551306298 -0.036 0 0 -1.57075</pose>
        <geometry>
          <mesh>
            <scale>0.001 0.001 0.001</scale>
            <uri>model://subwoofer_model/meshes/V1.02_Left_Hind_Limb.stl</uri>
          </mesh>
        </geometry>
      </visual>
    </link>
    <joint name='front_left_midlimb_servo_to_front_left_hip' type='revolute'>
      <pose relative_to='front_left_hip_servo'>0.0272 -0.025 -0.01 0 0 -1.57075</pose>
      <parent>front_left_hip_servo</parent>
      <child>front_left_midlimb_servo</child>
      <axis>
        <xyz>1 0 0</xyz>
        <limit>
          <lower>-1.5700000000000001</lower>
          <upper>1.5700000000000001</upper>
          <effort>1000</effort>
          <velocity>0.5</velocity>
        </limit>
        <dynamics>
          <damping>0.050000000000000003</damping>
          <friction>0.050000000000000003</friction>
          <spring_reference>0</spring_reference>
          <spring_stiffness>0</spring_stiffness>
        </dynamics>
      </axis>
    </joint>
    <link name='front_left_midlimb_servo'>
      <pose relative_to='front_left_midlimb_servo_to_front_left_hip'>0 0 0 0 0 0</pose>
      <inertial>
        <pose>0.02256666664888921 -0.008665899186098157 -0.07133333333333333 0 0 0</pose>
        <mass>0.14999999999999999</mass>
        <inertia>
          <ixx>0.0033872656691186359</ixx>
          <ixy>1.4664173577100751e-05</ixy>
          <ixz>0.0001207316665715573</ixz>
          <iyy>0.0034815796664739592</iyy>
          <iyz>-4.6362560645625107e-05</iyz>
          <izz>0.003105578668925928</izz>
        </inertia>
      </inertial>
      <collision name='front_left_midlimb_servo_collision'>
        <pose>0.043 0 -0.01 3.141592653589793 9.26535897930573e-05 -1.570842653589793</pose>
        <geometry>
          <mesh>
            <scale>0.001 0.001 0.001</scale>
            <uri>model://subwoofer_model/meshes/Servo.stl</uri>
          </mesh>
        </geometry>
      </collision>
      <collision name='front_left_midlimb_servo_fixed_joint_lump__front_left_midlimb_collision_1'>
        <pose>-0.01100222366469251 0.03499907341259428 0.7180000000000001 -3.141592653589793 9.26535897930573e-05 1.570842653589793</pose>
        <geometry>
          <mesh>
            <scale>0.001 0.001 0.001</scale>
            <uri>model://subwoofer_model/meshes/V1.02_Left_MidLimb.stl</uri>
          </mesh>
        </geometry>
      </collision>
      <collision name='front_left_midlimb_servo_fixed_joint_lump__front_left_midlimb_cover_collision_2'>
        <pose>-0.05128814027580373 -0.2690027932310213 0.8190000000000001 -3.141592653589793 9.26535897930573e-05 1.570842653589793</pose>
        <geometry>
          <mesh>
            <scale>0.001 0.001 0.001</scale>
            <uri>model://subwoofer_model/meshes/V1.02_Left_MidLimb_Cover.stl</uri>
          </mesh>
        </geometry>
      </collision>
      <visual name='front_left_midlimb_servo_visual'>
        <pose>0.043 0 -0.01 3.141592653589793 9.26535897930573e-05 -1.570842653589793</pose>
        <geometry>
          <mesh>
            <scale>0.001 0.001 0.001</scale>
            <uri>model://subwoofer_model/meshes/Servo.stl</uri>
          </mesh>
        </geometry>
      </visual>
      <visual name='front_left_midlimb_servo_fixed_joint_lump__front_left_midlimb_visual_1'>
        <pose>-0.01100222366469251 0.03499907341259428 0.7180000000000001 -3.141592653589793 9.26535897930573e-05 1.570842653589793</pose>
        <geometry>
          <mesh>
            <scale>0.001 0.001 0.001</scale>
            <uri>model://subwoofer_model/meshes/V1.02_Left_MidLimb.stl</uri>
          </mesh>
        </geometry>
      </visual>
      <visual name='front_left_midlimb_servo_fixed_joint_lump__front_left_midlimb_cover_visual_2'>
        <pose>-0.05128814027580373 -0.2690027932310213 0.8190000000000001 -3.141592653589793 9.26535897930573e-05 1.570842653589793</pose>
        <geometry>
          <mesh>
            <scale>0.001 0.001 0.001</scale>
            <uri>model://subwoofer_model/meshes/V1.02_Left_MidLimb_Cover.stl</uri>
          </mesh>
        </geometry>
      </visual>
    </link>
    <joint name='front_left_wrist_servo_to_front_left_midlimb' type='revolute'>
      <pose relative_to='front_left_midlimb_servo'>0.009000000000000001 -0.013 -0.107 0 0 0</pose>
      <parent>front_left_midlimb_servo</parent>
      <child>front_left_wrist_servo</child>
      <axis>
        <xyz>1 0 0</xyz>
        <limit>
          <lower>-2.6000000000000001</lower>
          <upper>1.1000000000000001</upper>
          <effort>1000</effort>
          <velocity>0.5</velocity>
        </limit>
        <dynamics>
          <damping>0.050000000000000003</damping>
          <friction>0.050000000000000003</friction>
          <spring_reference>0</spring_reference>
          <spring_stiffness>0</spring_stiffness>
        </dynamics>
      </axis>
    </joint>
    <link name='front_left_wrist_servo'>
      <pose relative_to='front_left_wrist_servo_to_front_left_midlimb'>0 0 0 0 0 0</pose>
      <inertial>
        <pose>0.0265 0 0 0 0 0</pose>
        <mass>0.10000000000000001</mass>
        <inertia>
          <ixx>0.002</ixx>
          <ixy>1.323488980084844e-23</ixy>
          <ixz>0</ixz>
          <iyy>0.0020702250000000002</iyy>
          <iyz>0</iyz>
          <izz>0.0020702250000000002</izz>
        </inertia>
      </inertial>
      <collision name='front_left_wrist_servo_collision'>
        <pose>0.043 0 -0.01 3.141592653589793 9.26535897930573e-05 -1.570842653589793</pose>
        <geometry>
          <mesh>
            <scale>0.001 0.001 0.001</scale>
            <uri>model://subwoofer_model/meshes/Servo.stl</uri>
          </mesh>
        </geometry>
      </collision>
      <collision name='front_left_wrist_servo_fixed_joint_lump__front_left_wrist_collision_1'>
        <pose>-0.4540217714173519 -0.2349530236213414 0.148 0 1.570796326794897 1.57075</pose>
        <geometry>
          <mesh>
            <scale>0.001 0.001 0.001</scale>
            <uri>model://subwoofer_model/meshes/V1.02_Left_Wrist.stl</uri>
          </mesh>
        </geometry>
      </collision>
      <visual name='front_left_wrist_servo_visual'>
        <pose>0.043 0 -0.01 3.141592653589793 9.26535897930573e-05 -1.570842653589793</pose>
        <geometry>
          <mesh>
            <scale>0.001 0.001 0.001</scale>
            <uri>model://subwoofer_model/meshes/Servo.stl</uri>
          </mesh>
        </geometry>
      </visual>
      <visual name='front_left_wrist_servo_fixed_joint_lump__front_left_wrist_visual_1'>
        <pose>-0.4540217714173519 -0.2349530236213414 0.148 0 1.570796326794897 1.57075</pose>
        <geometry>
          <mesh>
            <scale>0.001 0.001 0.001</scale>
            <uri>model://subwoofer_model/meshes/V1.02_Left_Wrist.stl</uri>
          </mesh>
        </geometry>
      </visual>
    </link>
    <joint name='front_right_hip_servo_to_front_outer_shoulder' type='revolute'>
      <pose relative_to='base_link'>0.037 0.119 0.017 0 0 -1.57075</pose>
      <parent>base_link</parent>
      <child>front_right_hip_servo</child>
      <axis>
        <xyz>1 0 0</xyz>
        <limit>
          <lower>-0.78000000000000003</lower>
          <upper>0.78000000000000003</upper>
          <effort>1000</effort>
          <velocity>0.5</velocity>
        </limit>
        <dynamics>
          <damping>0.050000000000000003</damping>
          <friction>0.050000000000000003</friction>
          <spring_reference>0</spring_reference>
          <spring_stiffness>0</spring_stiffness>
        </dynamics>
      </axis>
    </joint>
    <link name='front_right_hip_servo'>
      <pose relative_to='front_right_hip_servo_to_front_outer_shoulder'>0 0 0 0 0 0</pose>
      <inertial>
        <pose>0.0136 0.0125 -0.005 0 0 0</pose>
        <mass>0.10000000000000001</mass>
        <inertia>
          <ixx>0.002018125</ixx>
          <ixy>-1.7e-05</ixy>
          <ixz>6.7999999999999984e-06</ixz>
          <iyy>0.0020209960000000002</iyy>
          <iyz>6.2499999999999986e-06</iyz>
          <izz>0.0020341209999999998</izz>
        </inertia>
      </inertial>
      <collision name='front_right_hip_servo_collision'>
        <pose>0.043 0 -0.01 3.141592653589793 9.26535897930573e-05 -1.570842653589793</pose>
        <geometry>
          <mesh>
            <scale>0.001 0.001 0.001</scale>
            <uri>model://subwoofer_model/meshes/Servo.stl</uri>
          </mesh>
        </geometry>
      </collision>
      <collision name='front_right_hip_servo_fixed_joint_lump__front_right_hip_collision_1'>
        <pose>-0.07580555910485774 -0.09499522821135706 0.0182 3.1415 -6.776263578034403e-21 1.57075</pose>
        <geometry>
          <mesh>
            <scale>0.001 0.001 0.001</scale>
            <uri>model://subwoofer_model/meshes/V1.02_Right_Hind_Limb.stl</uri>
          </mesh>
        </geometry>
      </collision>
      <visual name='front_right_hip_servo_visual'>
        <pose>0.043 0 -0.01 3.141592653589793 9.26535897930573e-05 -1.570842653589793</pose>
        <geometry>
          <mesh>
            <scale>0.001 0.001 0.001</scale>
            <uri>model://subwoofer_model/meshes/Servo.stl</uri>
          </mesh>
        </geometry>
      </visual>
      <visual name='front_right_hip_servo_fixed_joint_lump__front_right_hip_visual_1'>
        <pose>-0.07580555910485774 -0.09499522821135706 0.0182 3.1415 -6.776263578034403e-21 1.57075</pose>
        <geometry>
          <mesh>
            <scale>0.001 0.001 0.001</scale>
            <uri>model://subwoofer_model/meshes/V1.02_Right_Hind_Limb.stl</uri>
          </mesh>
        </geometry>
      </visual>
    </link>
    <joint name='front_right_midlimb_servo_to_front_right_hip' type='revolute'>
      <pose relative_to='front_right_hip_servo'>0.0272 0.025 -0.01 0 0 1.57075</pose>
      <parent>front_right_hip_servo</parent>
      <child>front_right_midlimb_servo</child>
      <axis>
        <xyz>1 0 0</xyz>
        <limit>
          <lower>-1.5700000000000001</lower>
          <upper>1.5700000000000001</upper>
          <effort>1000</effort>
          <velocity>0.5</velocity>
        </limit>
        <dynamics>
          <damping>0.050000000000000003</damping>
          <friction>0.050000000000000003</friction>
          <spring_reference>0</spring_reference>
          <spring_stiffness>0</spring_stiffness>
        </dynamics>
      </axis>
    </joint>
    <link name='front_right_midlimb_servo'>
      <pose relative_to='front_right_midlimb_servo_to_front_right_hip'>0 0 0 0 0 0</pose>
      <inertial>
        <pose>0.02256666664888921 0.008667434147235179 -0.07133333333333333 0 0 0</pose>
        <mass>0.14999999999999999</mass>
        <inertia>
          <ixx>0.0033872676645681139</ixx>
          <ixy>-1.467249306645523e-05</ixy>
          <ixz>0.0001207316665715573</ixz>
          <iyy>0.0034815796664739592</iyy>
          <iyz>4.6370772687708167e-05</iyz>
          <izz>0.003105580664375406</izz>
        </inertia>
      </inertial>
      <collision name='front_right_midlimb_servo_collision'>
        <pose>0.043 0 -0.01 3.141592653589793 9.26535897930573e-05 -1.570842653589793</pose>
        <geometry>
          <mesh>
            <scale>0.001 0.001 0.001</scale>
            <uri>model://subwoofer_model/meshes/Servo.stl</uri>
          </mesh>
        </geometry>
      </collision>
      <collision name='front_right_midlimb_servo_fixed_joint_lump__front_right_midlimb_collision_1'>
        <pose>-0.01099777629238405 -0.03500092648438947 0.7180000000000001 0 0 -1.57075</pose>
        <geometry>
          <mesh>
            <scale>0.001 0.001 0.001</scale>
            <uri>model://subwoofer_model/meshes/V1.02_Right_MidLimb.stl</uri>
          </mesh>
        </geometry>
      </collision>
      <collision name='front_right_midlimb_servo_fixed_joint_lump__front_right_midlimb_cover_collision_2'>
        <pose>-0.05131185959478208 0.2689972062195588 0.8190000000000001 0 0 -1.57075</pose>
        <geometry>
          <mesh>
            <scale>0.001 0.001 0.001</scale>
            <uri>model://subwoofer_model/meshes/V1.02_Right_MidLimb_Cover.stl</uri>
          </mesh>
        </geometry>
      </collision>
      <visual name='front_right_midlimb_servo_visual'>
        <pose>0.043 0 -0.01 3.141592653589793 9.26535897930573e-05 -1.570842653589793</pose>
        <geometry>
          <mesh>
            <scale>0.001 0.001 0.001</scale>
            <uri>model://subwoofer_model/meshes/Servo.stl</uri>
          </mesh>
        </geometry>
      </visual>
      <visual name='front_right_midlimb_servo_fixed_joint_lump__front_right_midlimb_visual_1'>
        <pose>-0.01099777629238405 -0.03500092648438947 0.7180000000000001 0 0 -1.57075</pose>
        <geometry>
          <mesh>
            <scale>0.001 0.001 0.001</scale>
            <uri>model://subwoofer_model/meshes/V1.02_Right_MidLimb.stl</uri>
          </mesh>
        </geometry>
      </visual>
      <visual name='front_right_midlimb_servo_fixed_joint_lump__front_right_midlimb_cover_visual_2'>
        <pose>-0.05131185959478208 0.2689972062195588 0.8190000000000001 0 0 -1.57075</pose>
        <geometry>
          <mesh>
            <scale>0.001 0.001 0.001</scale>
            <uri>model://subwoofer_model/meshes/V1.02_Right_MidLimb_Cover.stl</uri>
          </mesh>
        </geometry>
      </visual>
    </link>
    <joint name='front_right_wrist_servo_to_front_right_midlimb' type='revolute'>
      <pose relative_to='front_right_midlimb_servo'>0.009000000000000001 0.013 -0.107 0 0 0</pose>
      <parent>front_right_midlimb_servo</parent>
      <child>front_right_wrist_servo</child>
      <axis>
        <xyz>1 0 0</xyz>
        <limit>
          <lower>-1.1000000000000001</lower>
          <upper>2.6000000000000001</upper>
          <effort>1000</effort>
          <velocity>0.5</velocity>
        </limit>
        <dynamics>
          <damping>0.050000000000000003</damping>
          <friction>0.050000000000000003</friction>
          <spring_reference>0</spring_reference>
          <spring_stiffness>0</spring_stiffness>
        </dynamics>
      </axis>
    </joint>
    <link name='front_right_wrist_servo'>
      <pose relative_to='front_right_wrist_servo_to_front_right_midlimb'>0 0 0 0 0 0</pose>
      <inertial>
        <pose>0.0265 0 0 0 0 0</pose>
        <mass>0.10000000000000001</mass>
        <inertia>
          <ixx>0.002</ixx>
          <ixy>0</ixy>
          <ixz>0</ixz>
          <iyy>0.0020702250000000002</iyy>
          <iyz>0</iyz>
          <izz>0.0020702250000000002</izz>
        </inertia>
      </inertial>
      <collision name='front_right_wrist_servo_collision'>
        <pose>0.043 0 -0.01 3.141592653589793 9.26535897930573e-05 -1.570842653589793</pose>
        <geometry>
          <mesh>
            <scale>0.001 0.001 0.001</scale>
            <uri>model://subwoofer_model/meshes/Servo.stl</uri>
          </mesh>
        </geometry>
      </collision>
      <collision name='front_right_wrist_servo_fixed_joint_lump__front_right_wrist_collision_1'>
        <pose>-0.454 0.235 0.148 0 1.570796326794897 1.57075</pose>
        <geometry>
          <mesh>
            <scale>0.001 0.001 0.001</scale>
            <uri>model://subwoofer_model/meshes/Right_Wrist.dae</uri>
          </mesh>
        </geometry>
      </collision>
      <visual name='front_right_wrist_servo_visual'>
        <pose>0.043 0 -0.01 3.141592653589793 9.26535897930573e-05 -1.570842653589793</pose>
        <geometry>
          <mesh>
            <scale>0.001 0.001 0.001</scale>
            <uri>model://subwoofer_model/meshes/Servo.stl</uri>
          </mesh>
        </geometry>
      </visual>
      <visual name='front_right_wrist_servo_fixed_joint_lump__front_right_wrist_visual_1'>
        <pose>-0.454 0.235 0.148 0 1.570796326794897 1.57075</pose>
        <geometry>
          <mesh>
            <scale>0.001 0.001 0.001</scale>
            <uri>model://subwoofer_model/meshes/Right_Wrist.dae</uri>
          </mesh>
        </geometry>
      </visual>
    </link>
    <frame name='back_outer_shoulder_to_back_inner_shoulder' attached_to='back_inner_shoulder'>
      <pose>0 -0.053 0 0 -0 0</pose>
    </frame>
    <frame name='back_outer_shoulder' attached_to='back_outer_shoulder_to_back_inner_shoulder'/>
    <frame name='rear_chassis_to_back_inner_shoulder' attached_to='back_inner_shoulder'>
      <pose>0 -0.079 0 0 -0 0</pose>
    </frame>
    <frame name='rear_chassis' attached_to='rear_chassis_to_back_inner_shoulder'/>
    <frame name='back_inner_shoulder_to_base_link' attached_to='base_link'>
      <pose>0 -0.066 0.01 0 -0 0</pose>
    </frame>
    <frame name='back_inner_shoulder' attached_to='back_inner_shoulder_to_base_link'/>
    <frame name='back_left_hip_to_back_left_hip_servo' attached_to='back_left_hip_servo'>
      <pose>0.0272 -0.025 -0.01 0 0 -1.57075</pose>
    </frame>
    <frame name='back_left_hip' attached_to='back_left_hip_to_back_left_hip_servo'/>
    <frame name='back_left_midlimb_cover_to_back_left_midlimb' attached_to='back_left_midlimb'>
      <pose>0 0.0497 0 0 -0 0</pose>
    </frame>
    <frame name='back_left_midlimb_cover' attached_to='back_left_midlimb_cover_to_back_left_midlimb'/>
    <frame name='back_left_midlimb_to_back_left_midlimb_servo' attached_to='back_left_midlimb_servo'>
      <pose>0.009 -0.013 -0.107 0 0 -1.57075</pose>
    </frame>
    <frame name='back_left_midlimb' attached_to='back_left_midlimb_to_back_left_midlimb_servo'/>
    <frame name='back_left_wrist_to_back_left_wrist_servo' attached_to='back_left_wrist_servo'>
      <pose>0.053 0 0 0 -0 3.1415</pose>
    </frame>
    <frame name='back_left_wrist' attached_to='back_left_wrist_to_back_left_wrist_servo'/>
    <frame name='back_right_hip_to_back_right_hip_servo' attached_to='back_right_hip_servo'>
      <pose>0.0272 0.025 -0.01 0 -0 1.57075</pose>
    </frame>
    <frame name='back_right_hip' attached_to='back_right_hip_to_back_right_hip_servo'/>
    <frame name='back_right_midlimb_cover_to_back_right_midlimb' attached_to='back_right_midlimb'>
      <pose>0 0.0497 0 0 -0 0</pose>
    </frame>
    <frame name='back_right_midlimb_cover' attached_to='back_right_midlimb_cover_to_back_right_midlimb'/>
    <frame name='back_right_midlimb_to_back_right_midlimb_servo' attached_to='back_right_midlimb_servo'>
      <pose>0.009 0.013 -0.107 0 0 -1.57075</pose>
    </frame>
    <frame name='back_right_midlimb' attached_to='back_right_midlimb_to_back_right_midlimb_servo'/>
    <frame name='back_right_wrist_to_back_right_wrist_servo' attached_to='back_right_wrist_servo'>
      <pose>0.053 0 0 0 -0 0</pose>
    </frame>
    <frame name='back_right_wrist' attached_to='back_right_wrist_to_back_right_wrist_servo'/>
    <frame name='top_chassis_to_bottom_chassis' attached_to='bottom_chassis'>
      <pose>0 0 0.072 0 -0 0</pose>
    </frame>
    <frame name='top_chassis' attached_to='top_chassis_to_bottom_chassis'/>
    <frame name='bottom_chassis_to_base_link' attached_to='base_link'>
      <pose>0 0 -0.028 0 -0 0</pose>
    </frame>
    <frame name='bottom_chassis' attached_to='bottom_chassis_to_base_link'/>
    <frame name='front_outer_shoulder_to_front_inner_shoulder' attached_to='front_inner_shoulder'>
      <pose>0 0.054 0 0 -0 0</pose>
    </frame>
    <frame name='front_outer_shoulder' attached_to='front_outer_shoulder_to_front_inner_shoulder'/>
    <frame name='front_left_hip_to_front_left_hip_servo' attached_to='front_left_hip_servo'>
      <pose>0.0272 -0.025 -0.01 0 0 -1.57075</pose>
    </frame>
    <frame name='front_left_hip' attached_to='front_left_hip_to_front_left_hip_servo'/>
    <frame name='front_left_midlimb_cover_to_front_left_midlimb' attached_to='front_left_midlimb'>
      <pose>0 0.0497 0 0 -0 0</pose>
    </frame>
    <frame name='front_left_midlimb_cover' attached_to='front_left_midlimb_cover_to_front_left_midlimb'/>
    <frame name='front_left_midlimb_to_front_left_midlimb_servo' attached_to='front_left_midlimb_servo'>
      <pose>0.009 -0.013 -0.107 0 0 -1.57075</pose>
    </frame>
    <frame name='front_left_midlimb' attached_to='front_left_midlimb_to_front_left_midlimb_servo'/>
    <frame name='front_left_wrist_to_front_left_wrist_servo' attached_to='front_left_wrist_servo'>
      <pose>0.053 0 0 0 -0 3.1415</pose>
    </frame>
    <frame name='front_left_wrist' attached_to='front_left_wrist_to_front_left_wrist_servo'/>
    <frame name='front_right_hip_to_front_right_hip_servo' attached_to='front_right_hip_servo'>
      <pose>0.0272 0.025 -0.01 0 -0 1.57075</pose>
    </frame>
    <frame name='front_right_hip' attached_to='front_right_hip_to_front_right_hip_servo'/>
    <frame name='front_right_midlimb_cover_to_front_right_midlimb' attached_to='front_right_midlimb'>
      <pose>0 0.0497 0 0 -0 0</pose>
    </frame>
    <frame name='front_right_midlimb_cover' attached_to='front_right_midlimb_cover_to_front_right_midlimb'/>
    <frame name='front_right_midlimb_to_front_right_midlimb_servo' attached_to='front_right_midlimb_servo'>
      <pose>0.009 0.013 -0.107 0 0 -1.57075</pose>
    </frame>
    <frame name='front_right_midlimb' attached_to='front_right_midlimb_to_front_right_midlimb_servo'/>
    <frame name='front_right_wrist_to_front_right_wrist_servo' attached_to='front_right_wrist_servo'>
      <pose>0.053 0 0 0 -0 0</pose>
    </frame>
    <frame name='front_right_wrist' attached_to='front_right_wrist_to_front_right_wrist_servo'/>
    <frame name='left_chassis_to_front_inner_shoulder' attached_to='front_inner_shoulder'>
      <pose>-0.054 -0.0655 0.0005 -0 -1.57075 3.1415</pose>
    </frame>
    <frame name='left_chassis' attached_to='left_chassis_to_front_inner_shoulder'/>
    <frame name='nose_chassis_to_front_inner_shoulder' attached_to='front_inner_shoulder'>
      <pose>0 0.074 -0.0075 0 -0 0</pose>
    </frame>
    <frame name='nose_chassis' attached_to='nose_chassis_to_front_inner_shoulder'/>
    <frame name='right_chassis_to_front_inner_shoulder' attached_to='front_inner_shoulder'>
      <pose>0.054 -0.0655 0.0005 0 -1.57075 0</pose>
    </frame>
    <frame name='right_chassis' attached_to='right_chassis_to_front_inner_shoulder'/>
    <frame name='front_inner_shoulder_to_base_link' attached_to='base_link'>
      <pose>0 0.065 0.01 0 -0 0</pose>
    </frame>
    <frame name='front_inner_shoulder' attached_to='front_inner_shoulder_to_base_link'/>
  </model>
</sdf>
